2025-07-07 13:06:35,005 INFO    MainThread:956308 [wandb_setup.py:_flush():80] Current SDK version is 0.21.0
2025-07-07 13:06:35,005 INFO    MainThread:956308 [wandb_setup.py:_flush():80] Configure stats pid to 956308
2025-07-07 13:06:35,005 INFO    MainThread:956308 [wandb_setup.py:_flush():80] Loading settings from /home/vcivale/.config/wandb/settings
2025-07-07 13:06:35,005 INFO    MainThread:956308 [wandb_setup.py:_flush():80] Loading settings from /home/vcivale/scTumorClassificationPipeline/wandb/settings
2025-07-07 13:06:35,006 INFO    MainThread:956308 [wandb_setup.py:_flush():80] Loading settings from environment variables
2025-07-07 13:06:35,006 INFO    MainThread:956308 [wandb_init.py:setup_run_log_directory():703] Logging user logs to /home/vcivale/scTumorClassificationPipeline/wandb/run-20250707_130634-bzpbx4cc/logs/debug.log
2025-07-07 13:06:35,006 INFO    MainThread:956308 [wandb_init.py:setup_run_log_directory():704] Logging internal logs to /home/vcivale/scTumorClassificationPipeline/wandb/run-20250707_130634-bzpbx4cc/logs/debug-internal.log
2025-07-07 13:06:35,006 INFO    MainThread:956308 [wandb_init.py:monkeypatch_ipython():622] configuring jupyter hooks <wandb.sdk.wandb_init._WandbInit object at 0x7f25300499f0>
2025-07-07 13:06:35,007 INFO    MainThread:956308 [wandb_init.py:init():830] calling init triggers
2025-07-07 13:06:35,007 INFO    MainThread:956308 [wandb_init.py:init():835] wandb.init called with sweep_config: {}
config: {'_wandb': {}}
2025-07-07 13:06:35,007 INFO    MainThread:956308 [wandb_init.py:init():871] starting backend
2025-07-07 13:06:35,223 INFO    MainThread:956308 [wandb_init.py:init():874] sending inform_init request
2025-07-07 13:06:35,228 INFO    MainThread:956308 [wandb_init.py:init():882] backend started and connected
2025-07-07 13:06:35,240 INFO    MainThread:956308 [wandb_run.py:_label_probe_notebook():1304] probe notebook
2025-07-07 13:06:35,243 INFO    MainThread:956308 [wandb_init.py:init():953] updated telemetry
2025-07-07 13:06:35,254 INFO    MainThread:956308 [wandb_init.py:init():977] communicating run to backend with 90.0 second timeout
2025-07-07 13:06:35,925 INFO    MainThread:956308 [wandb_init.py:init():1029] starting run threads in backend
2025-07-07 13:06:36,227 INFO    MainThread:956308 [wandb_run.py:_console_start():2458] atexit reg
2025-07-07 13:06:36,227 INFO    MainThread:956308 [wandb_run.py:_redirect():2306] redirect: wrap_raw
2025-07-07 13:06:36,227 INFO    MainThread:956308 [wandb_run.py:_redirect():2375] Wrapping output streams.
2025-07-07 13:06:36,227 INFO    MainThread:956308 [wandb_run.py:_redirect():2398] Redirects installed.
2025-07-07 13:06:36,246 INFO    MainThread:956308 [wandb_init.py:init():1075] run started, returning control to user process
2025-07-07 13:06:36,351 INFO    MainThread:956308 [wandb_init.py:_post_run_cell_hook():592] [no run ID] resuming backend
2025-07-07 13:06:36,469 INFO    MainThread:956308 [jupyter.py:save_ipynb():404] [no run ID] not saving jupyter notebook
2025-07-07 13:06:36,469 INFO    MainThread:956308 [wandb_init.py:_pre_run_cell_hook():581] [no run ID] pausing backend
2025-07-07 13:06:37,456 INFO    MainThread:956308 [wandb_run.py:_config_callback():1363] config_cb None None {'output_dir': '/equilibrium/datasets/TCGA-histological-data/lung/checkpoints/AdvancedMLPClassifier_hdim_3072x1536x768_2025-07-07_13-06-34', 'overwrite_output_dir': False, 'do_train': False, 'do_eval': True, 'do_predict': False, 'eval_strategy': 'steps', 'prediction_loss_only': False, 'per_device_train_batch_size': 1024, 'per_device_eval_batch_size': 1024, 'per_gpu_train_batch_size': None, 'per_gpu_eval_batch_size': None, 'gradient_accumulation_steps': 1, 'eval_accumulation_steps': None, 'eval_delay': 0, 'torch_empty_cache_steps': None, 'learning_rate': 0.001, 'weight_decay': 0.01, 'adam_beta1': 0.9, 'adam_beta2': 0.999, 'adam_epsilon': 1e-08, 'max_grad_norm': 1.0, 'num_train_epochs': 150, 'max_steps': -1, 'lr_scheduler_type': 'cosine', 'lr_scheduler_kwargs': {}, 'warmup_ratio': 0.1, 'warmup_steps': 0, 'log_level': 'passive', 'log_level_replica': 'warning', 'log_on_each_node': True, 'logging_dir': './logs', 'logging_strategy': 'steps', 'logging_first_step': False, 'logging_steps': 100, 'logging_nan_inf_filter': True, 'save_strategy': 'steps', 'save_steps': 400, 'save_total_limit': 3, 'save_safetensors': True, 'save_on_each_node': False, 'save_only_model': False, 'restore_callback_states_from_checkpoint': False, 'no_cuda': False, 'use_cpu': False, 'use_mps_device': False, 'seed': 42, 'data_seed': None, 'jit_mode_eval': False, 'use_ipex': False, 'bf16': False, 'fp16': True, 'fp16_opt_level': 'O1', 'half_precision_backend': 'auto', 'bf16_full_eval': False, 'fp16_full_eval': False, 'tf32': None, 'local_rank': 0, 'ddp_backend': None, 'tpu_num_cores': None, 'tpu_metrics_debug': False, 'debug': [], 'dataloader_drop_last': False, 'eval_steps': 200, 'dataloader_num_workers': 8, 'dataloader_prefetch_factor': None, 'past_index': -1, 'run_name': 'AdvancedMLPClassifier_hdim_3072x1536x768_2025-07-07_13-06-34', 'disable_tqdm': False, 'remove_unused_columns': True, 'label_names': None, 'load_best_model_at_end': True, 'metric_for_best_model': 'f1', 'greater_is_better': True, 'ignore_data_skip': True, 'fsdp': [], 'fsdp_min_num_params': 0, 'fsdp_config': {'min_num_params': 0, 'xla': False, 'xla_fsdp_v2': False, 'xla_fsdp_grad_ckpt': False}, 'fsdp_transformer_layer_cls_to_wrap': None, 'accelerator_config': {'split_batches': False, 'dispatch_batches': None, 'even_batches': True, 'use_seedable_sampler': True, 'non_blocking': False, 'gradient_accumulation_kwargs': None}, 'deepspeed': None, 'label_smoothing_factor': 0.0, 'optim': 'adamw_torch', 'optim_args': None, 'adafactor': False, 'group_by_length': False, 'length_column_name': 'length', 'report_to': ['wandb'], 'ddp_find_unused_parameters': None, 'ddp_bucket_cap_mb': None, 'ddp_broadcast_buffers': None, 'dataloader_pin_memory': True, 'dataloader_persistent_workers': False, 'skip_memory_metrics': True, 'use_legacy_prediction_loop': False, 'push_to_hub': False, 'resume_from_checkpoint': None, 'hub_model_id': None, 'hub_strategy': 'every_save', 'hub_token': '<HUB_TOKEN>', 'hub_private_repo': None, 'hub_always_push': False, 'hub_revision': None, 'gradient_checkpointing': False, 'gradient_checkpointing_kwargs': None, 'include_inputs_for_metrics': False, 'include_for_metrics': [], 'eval_do_concat_batches': True, 'fp16_backend': 'auto', 'push_to_hub_model_id': None, 'push_to_hub_organization': None, 'push_to_hub_token': '<PUSH_TO_HUB_TOKEN>', 'mp_parameters': '', 'auto_find_batch_size': False, 'full_determinism': False, 'torchdynamo': None, 'ray_scope': 'last', 'ddp_timeout': 1800, 'torch_compile': False, 'torch_compile_backend': None, 'torch_compile_mode': None, 'include_tokens_per_second': False, 'include_num_input_tokens_seen': False, 'neftune_noise_alpha': None, 'optim_target_modules': None, 'batch_eval_metrics': False, 'eval_on_start': False, 'use_liger_kernel': False, 'liger_kernel_config': None, 'eval_use_gather_object': False, 'average_tokens_across_devices': False}
2025-07-07 13:06:44,449 WARNING MsgRouterThr:956308 [router.py:message_loop():63] [no run ID] message_loop has been closed
Traceback (most recent call last):
  File "/home/vcivale/.local/lib/python3.10/site-packages/wandb/sdk/interface/router_sock.py", line 27, in _read_message
    return self._sock_client.read_server_response(timeout=1)
  File "/home/vcivale/.local/lib/python3.10/site-packages/wandb/sdk/lib/sock_client.py", line 231, in read_server_response
    data = self._read_packet_bytes(timeout=timeout)
  File "/home/vcivale/.local/lib/python3.10/site-packages/wandb/sdk/lib/sock_client.py", line 216, in _read_packet_bytes
    raise SockClientClosedError
wandb.sdk.lib.sock_client.SockClientClosedError

The above exception was the direct cause of the following exception:

Traceback (most recent call last):
  File "/home/vcivale/.local/lib/python3.10/site-packages/wandb/sdk/interface/router.py", line 56, in message_loop
    msg = self._read_message()
  File "/home/vcivale/.local/lib/python3.10/site-packages/wandb/sdk/interface/router_sock.py", line 29, in _read_message
    raise MessageRouterClosedError from e
wandb.sdk.interface.router.MessageRouterClosedError
2025-07-07 13:06:44,504 INFO    MsgRouterThr:956308 [mailbox.py:close():129] [no run ID] Closing mailbox, abandoning 1 handles.
2025-07-07 13:06:45,475 INFO    MainThread:956308 [wandb_init.py:_post_run_cell_hook():592] [no run ID] resuming backend
2025-07-07 13:06:45,476 ERROR   MainThread:956308 [redirect.py:_on_write():664] [all runs] error in stdout callback
Traceback (most recent call last):
  File "/home/vcivale/.local/lib/python3.10/site-packages/IPython/core/events.py", line 82, in trigger
    func(*args, **kwargs)
  File "/home/vcivale/.local/lib/python3.10/site-packages/wandb/sdk/wandb_init.py", line 593, in _post_run_cell_hook
    self.backend.interface.publish_resume()
  File "/home/vcivale/.local/lib/python3.10/site-packages/wandb/sdk/interface/interface.py", line 787, in publish_resume
    self._publish_resume(resume)
  File "/home/vcivale/.local/lib/python3.10/site-packages/wandb/sdk/interface/interface_shared.py", line 294, in _publish_resume
    self._publish(rec)
  File "/home/vcivale/.local/lib/python3.10/site-packages/wandb/sdk/interface/interface_sock.py", line 39, in _publish
    self._sock_client.send_record_publish(record)
  File "/home/vcivale/.local/lib/python3.10/site-packages/wandb/sdk/lib/sock_client.py", line 170, in send_record_publish
    self.send_server_request(server_req)
  File "/home/vcivale/.local/lib/python3.10/site-packages/wandb/sdk/lib/sock_client.py", line 150, in send_server_request
    self._send_message(msg)
  File "/home/vcivale/.local/lib/python3.10/site-packages/wandb/sdk/lib/sock_client.py", line 147, in _send_message
    self._sendall_with_error_handle(header + data)
  File "/home/vcivale/.local/lib/python3.10/site-packages/wandb/sdk/lib/sock_client.py", line 126, in _sendall_with_error_handle
    sent = self._sock.send(data)
BrokenPipeError: [Errno 32] Broken pipe

During handling of the above exception, another exception occurred:

Traceback (most recent call last):
  File "/home/vcivale/.local/lib/python3.10/site-packages/wandb/sdk/lib/redirect.py", line 662, in _on_write
    cb(written_data)
  File "/home/vcivale/.local/lib/python3.10/site-packages/wandb/sdk/wandb_run.py", line 2379, in <lambda>
    lambda data: self._console_raw_callback("stdout", data),
  File "/home/vcivale/.local/lib/python3.10/site-packages/wandb/sdk/wandb_run.py", line 398, in wrapper
    return func(self, *args, **kwargs)
  File "/home/vcivale/.local/lib/python3.10/site-packages/wandb/sdk/wandb_run.py", line 456, in wrapper_fn
    return func(self, *args, **kwargs)
  File "/home/vcivale/.local/lib/python3.10/site-packages/wandb/sdk/wandb_run.py", line 1566, in _console_raw_callback
    self._backend.interface.publish_output_raw(name, data)
  File "/home/vcivale/.local/lib/python3.10/site-packages/wandb/sdk/interface/interface.py", line 771, in publish_output_raw
    self._publish_output_raw(o)
  File "/home/vcivale/.local/lib/python3.10/site-packages/wandb/sdk/interface/interface_shared.py", line 38, in _publish_output_raw
    self._publish(rec)
  File "/home/vcivale/.local/lib/python3.10/site-packages/wandb/sdk/interface/interface_sock.py", line 39, in _publish
    self._sock_client.send_record_publish(record)
  File "/home/vcivale/.local/lib/python3.10/site-packages/wandb/sdk/lib/sock_client.py", line 170, in send_record_publish
    self.send_server_request(server_req)
  File "/home/vcivale/.local/lib/python3.10/site-packages/wandb/sdk/lib/sock_client.py", line 150, in send_server_request
    self._send_message(msg)
  File "/home/vcivale/.local/lib/python3.10/site-packages/wandb/sdk/lib/sock_client.py", line 147, in _send_message
    self._sendall_with_error_handle(header + data)
  File "/home/vcivale/.local/lib/python3.10/site-packages/wandb/sdk/lib/sock_client.py", line 126, in _sendall_with_error_handle
    sent = self._sock.send(data)
BrokenPipeError: [Errno 32] Broken pipe
2025-07-07 13:06:45,490 ERROR   MainThread:956308 [redirect.py:_on_write():664] [all runs] error in stdout callback
Traceback (most recent call last):
  File "/home/vcivale/.local/lib/python3.10/site-packages/IPython/core/events.py", line 82, in trigger
    func(*args, **kwargs)
  File "/home/vcivale/.local/lib/python3.10/site-packages/wandb/sdk/wandb_init.py", line 593, in _post_run_cell_hook
    self.backend.interface.publish_resume()
  File "/home/vcivale/.local/lib/python3.10/site-packages/wandb/sdk/interface/interface.py", line 787, in publish_resume
    self._publish_resume(resume)
  File "/home/vcivale/.local/lib/python3.10/site-packages/wandb/sdk/interface/interface_shared.py", line 294, in _publish_resume
    self._publish(rec)
  File "/home/vcivale/.local/lib/python3.10/site-packages/wandb/sdk/interface/interface_sock.py", line 39, in _publish
    self._sock_client.send_record_publish(record)
  File "/home/vcivale/.local/lib/python3.10/site-packages/wandb/sdk/lib/sock_client.py", line 170, in send_record_publish
    self.send_server_request(server_req)
  File "/home/vcivale/.local/lib/python3.10/site-packages/wandb/sdk/lib/sock_client.py", line 150, in send_server_request
    self._send_message(msg)
  File "/home/vcivale/.local/lib/python3.10/site-packages/wandb/sdk/lib/sock_client.py", line 147, in _send_message
    self._sendall_with_error_handle(header + data)
  File "/home/vcivale/.local/lib/python3.10/site-packages/wandb/sdk/lib/sock_client.py", line 126, in _sendall_with_error_handle
    sent = self._sock.send(data)
BrokenPipeError: [Errno 32] Broken pipe

During handling of the above exception, another exception occurred:

Traceback (most recent call last):
  File "/home/vcivale/.local/lib/python3.10/site-packages/wandb/sdk/lib/redirect.py", line 662, in _on_write
    cb(written_data)
  File "/home/vcivale/.local/lib/python3.10/site-packages/wandb/sdk/wandb_run.py", line 2379, in <lambda>
    lambda data: self._console_raw_callback("stdout", data),
  File "/home/vcivale/.local/lib/python3.10/site-packages/wandb/sdk/wandb_run.py", line 398, in wrapper
    return func(self, *args, **kwargs)
  File "/home/vcivale/.local/lib/python3.10/site-packages/wandb/sdk/wandb_run.py", line 456, in wrapper_fn
    return func(self, *args, **kwargs)
  File "/home/vcivale/.local/lib/python3.10/site-packages/wandb/sdk/wandb_run.py", line 1566, in _console_raw_callback
    self._backend.interface.publish_output_raw(name, data)
  File "/home/vcivale/.local/lib/python3.10/site-packages/wandb/sdk/interface/interface.py", line 771, in publish_output_raw
    self._publish_output_raw(o)
  File "/home/vcivale/.local/lib/python3.10/site-packages/wandb/sdk/interface/interface_shared.py", line 38, in _publish_output_raw
    self._publish(rec)
  File "/home/vcivale/.local/lib/python3.10/site-packages/wandb/sdk/interface/interface_sock.py", line 39, in _publish
    self._sock_client.send_record_publish(record)
  File "/home/vcivale/.local/lib/python3.10/site-packages/wandb/sdk/lib/sock_client.py", line 170, in send_record_publish
    self.send_server_request(server_req)
  File "/home/vcivale/.local/lib/python3.10/site-packages/wandb/sdk/lib/sock_client.py", line 150, in send_server_request
    self._send_message(msg)
  File "/home/vcivale/.local/lib/python3.10/site-packages/wandb/sdk/lib/sock_client.py", line 147, in _send_message
    self._sendall_with_error_handle(header + data)
  File "/home/vcivale/.local/lib/python3.10/site-packages/wandb/sdk/lib/sock_client.py", line 126, in _sendall_with_error_handle
    sent = self._sock.send(data)
BrokenPipeError: [Errno 32] Broken pipe
2025-07-07 13:09:31,124 INFO    MainThread:956308 [jupyter.py:save_ipynb():404] [no run ID] not saving jupyter notebook
2025-07-07 13:09:31,125 INFO    MainThread:956308 [wandb_init.py:_pre_run_cell_hook():581] [no run ID] pausing backend
2025-07-07 13:09:31,126 ERROR   MainThread:956308 [redirect.py:_on_write():664] [all runs] error in stdout callback
Traceback (most recent call last):
  File "/home/vcivale/.local/lib/python3.10/site-packages/IPython/core/events.py", line 82, in trigger
    func(*args, **kwargs)
  File "/home/vcivale/.local/lib/python3.10/site-packages/wandb/sdk/wandb_init.py", line 582, in _pre_run_cell_hook
    self.backend.interface.publish_pause()
  File "/home/vcivale/.local/lib/python3.10/site-packages/wandb/sdk/interface/interface.py", line 779, in publish_pause
    self._publish_pause(pause)
  File "/home/vcivale/.local/lib/python3.10/site-packages/wandb/sdk/interface/interface_shared.py", line 290, in _publish_pause
    self._publish(rec)
  File "/home/vcivale/.local/lib/python3.10/site-packages/wandb/sdk/interface/interface_sock.py", line 39, in _publish
    self._sock_client.send_record_publish(record)
  File "/home/vcivale/.local/lib/python3.10/site-packages/wandb/sdk/lib/sock_client.py", line 170, in send_record_publish
    self.send_server_request(server_req)
  File "/home/vcivale/.local/lib/python3.10/site-packages/wandb/sdk/lib/sock_client.py", line 150, in send_server_request
    self._send_message(msg)
  File "/home/vcivale/.local/lib/python3.10/site-packages/wandb/sdk/lib/sock_client.py", line 147, in _send_message
    self._sendall_with_error_handle(header + data)
  File "/home/vcivale/.local/lib/python3.10/site-packages/wandb/sdk/lib/sock_client.py", line 126, in _sendall_with_error_handle
    sent = self._sock.send(data)
BrokenPipeError: [Errno 32] Broken pipe

During handling of the above exception, another exception occurred:

Traceback (most recent call last):
  File "/home/vcivale/.local/lib/python3.10/site-packages/wandb/sdk/lib/redirect.py", line 662, in _on_write
    cb(written_data)
  File "/home/vcivale/.local/lib/python3.10/site-packages/wandb/sdk/wandb_run.py", line 2379, in <lambda>
    lambda data: self._console_raw_callback("stdout", data),
  File "/home/vcivale/.local/lib/python3.10/site-packages/wandb/sdk/wandb_run.py", line 398, in wrapper
    return func(self, *args, **kwargs)
  File "/home/vcivale/.local/lib/python3.10/site-packages/wandb/sdk/wandb_run.py", line 456, in wrapper_fn
    return func(self, *args, **kwargs)
  File "/home/vcivale/.local/lib/python3.10/site-packages/wandb/sdk/wandb_run.py", line 1566, in _console_raw_callback
    self._backend.interface.publish_output_raw(name, data)
  File "/home/vcivale/.local/lib/python3.10/site-packages/wandb/sdk/interface/interface.py", line 771, in publish_output_raw
    self._publish_output_raw(o)
  File "/home/vcivale/.local/lib/python3.10/site-packages/wandb/sdk/interface/interface_shared.py", line 38, in _publish_output_raw
    self._publish(rec)
  File "/home/vcivale/.local/lib/python3.10/site-packages/wandb/sdk/interface/interface_sock.py", line 39, in _publish
    self._sock_client.send_record_publish(record)
  File "/home/vcivale/.local/lib/python3.10/site-packages/wandb/sdk/lib/sock_client.py", line 170, in send_record_publish
    self.send_server_request(server_req)
  File "/home/vcivale/.local/lib/python3.10/site-packages/wandb/sdk/lib/sock_client.py", line 150, in send_server_request
    self._send_message(msg)
  File "/home/vcivale/.local/lib/python3.10/site-packages/wandb/sdk/lib/sock_client.py", line 147, in _send_message
    self._sendall_with_error_handle(header + data)
  File "/home/vcivale/.local/lib/python3.10/site-packages/wandb/sdk/lib/sock_client.py", line 126, in _sendall_with_error_handle
    sent = self._sock.send(data)
BrokenPipeError: [Errno 32] Broken pipe
2025-07-07 13:09:31,128 ERROR   MainThread:956308 [redirect.py:_on_write():664] [all runs] error in stdout callback
Traceback (most recent call last):
  File "/home/vcivale/.local/lib/python3.10/site-packages/IPython/core/events.py", line 82, in trigger
    func(*args, **kwargs)
  File "/home/vcivale/.local/lib/python3.10/site-packages/wandb/sdk/wandb_init.py", line 582, in _pre_run_cell_hook
    self.backend.interface.publish_pause()
  File "/home/vcivale/.local/lib/python3.10/site-packages/wandb/sdk/interface/interface.py", line 779, in publish_pause
    self._publish_pause(pause)
  File "/home/vcivale/.local/lib/python3.10/site-packages/wandb/sdk/interface/interface_shared.py", line 290, in _publish_pause
    self._publish(rec)
  File "/home/vcivale/.local/lib/python3.10/site-packages/wandb/sdk/interface/interface_sock.py", line 39, in _publish
    self._sock_client.send_record_publish(record)
  File "/home/vcivale/.local/lib/python3.10/site-packages/wandb/sdk/lib/sock_client.py", line 170, in send_record_publish
    self.send_server_request(server_req)
  File "/home/vcivale/.local/lib/python3.10/site-packages/wandb/sdk/lib/sock_client.py", line 150, in send_server_request
    self._send_message(msg)
  File "/home/vcivale/.local/lib/python3.10/site-packages/wandb/sdk/lib/sock_client.py", line 147, in _send_message
    self._sendall_with_error_handle(header + data)
  File "/home/vcivale/.local/lib/python3.10/site-packages/wandb/sdk/lib/sock_client.py", line 126, in _sendall_with_error_handle
    sent = self._sock.send(data)
BrokenPipeError: [Errno 32] Broken pipe

During handling of the above exception, another exception occurred:

Traceback (most recent call last):
  File "/home/vcivale/.local/lib/python3.10/site-packages/wandb/sdk/lib/redirect.py", line 662, in _on_write
    cb(written_data)
  File "/home/vcivale/.local/lib/python3.10/site-packages/wandb/sdk/wandb_run.py", line 2379, in <lambda>
    lambda data: self._console_raw_callback("stdout", data),
  File "/home/vcivale/.local/lib/python3.10/site-packages/wandb/sdk/wandb_run.py", line 398, in wrapper
    return func(self, *args, **kwargs)
  File "/home/vcivale/.local/lib/python3.10/site-packages/wandb/sdk/wandb_run.py", line 456, in wrapper_fn
    return func(self, *args, **kwargs)
  File "/home/vcivale/.local/lib/python3.10/site-packages/wandb/sdk/wandb_run.py", line 1566, in _console_raw_callback
    self._backend.interface.publish_output_raw(name, data)
  File "/home/vcivale/.local/lib/python3.10/site-packages/wandb/sdk/interface/interface.py", line 771, in publish_output_raw
    self._publish_output_raw(o)
  File "/home/vcivale/.local/lib/python3.10/site-packages/wandb/sdk/interface/interface_shared.py", line 38, in _publish_output_raw
    self._publish(rec)
  File "/home/vcivale/.local/lib/python3.10/site-packages/wandb/sdk/interface/interface_sock.py", line 39, in _publish
    self._sock_client.send_record_publish(record)
  File "/home/vcivale/.local/lib/python3.10/site-packages/wandb/sdk/lib/sock_client.py", line 170, in send_record_publish
    self.send_server_request(server_req)
  File "/home/vcivale/.local/lib/python3.10/site-packages/wandb/sdk/lib/sock_client.py", line 150, in send_server_request
    self._send_message(msg)
  File "/home/vcivale/.local/lib/python3.10/site-packages/wandb/sdk/lib/sock_client.py", line 147, in _send_message
    self._sendall_with_error_handle(header + data)
  File "/home/vcivale/.local/lib/python3.10/site-packages/wandb/sdk/lib/sock_client.py", line 126, in _sendall_with_error_handle
    sent = self._sock.send(data)
BrokenPipeError: [Errno 32] Broken pipe
2025-07-07 13:09:31,230 INFO    MainThread:956308 [wandb_init.py:_post_run_cell_hook():592] [no run ID] resuming backend
2025-07-07 13:09:31,230 ERROR   MainThread:956308 [redirect.py:_on_write():664] [all runs] error in stdout callback
Traceback (most recent call last):
  File "/home/vcivale/.local/lib/python3.10/site-packages/IPython/core/events.py", line 82, in trigger
    func(*args, **kwargs)
  File "/home/vcivale/.local/lib/python3.10/site-packages/wandb/sdk/wandb_init.py", line 593, in _post_run_cell_hook
    self.backend.interface.publish_resume()
  File "/home/vcivale/.local/lib/python3.10/site-packages/wandb/sdk/interface/interface.py", line 787, in publish_resume
    self._publish_resume(resume)
  File "/home/vcivale/.local/lib/python3.10/site-packages/wandb/sdk/interface/interface_shared.py", line 294, in _publish_resume
    self._publish(rec)
  File "/home/vcivale/.local/lib/python3.10/site-packages/wandb/sdk/interface/interface_sock.py", line 39, in _publish
    self._sock_client.send_record_publish(record)
  File "/home/vcivale/.local/lib/python3.10/site-packages/wandb/sdk/lib/sock_client.py", line 170, in send_record_publish
    self.send_server_request(server_req)
  File "/home/vcivale/.local/lib/python3.10/site-packages/wandb/sdk/lib/sock_client.py", line 150, in send_server_request
    self._send_message(msg)
  File "/home/vcivale/.local/lib/python3.10/site-packages/wandb/sdk/lib/sock_client.py", line 147, in _send_message
    self._sendall_with_error_handle(header + data)
  File "/home/vcivale/.local/lib/python3.10/site-packages/wandb/sdk/lib/sock_client.py", line 126, in _sendall_with_error_handle
    sent = self._sock.send(data)
BrokenPipeError: [Errno 32] Broken pipe

During handling of the above exception, another exception occurred:

Traceback (most recent call last):
  File "/home/vcivale/.local/lib/python3.10/site-packages/wandb/sdk/lib/redirect.py", line 662, in _on_write
    cb(written_data)
  File "/home/vcivale/.local/lib/python3.10/site-packages/wandb/sdk/wandb_run.py", line 2379, in <lambda>
    lambda data: self._console_raw_callback("stdout", data),
  File "/home/vcivale/.local/lib/python3.10/site-packages/wandb/sdk/wandb_run.py", line 398, in wrapper
    return func(self, *args, **kwargs)
  File "/home/vcivale/.local/lib/python3.10/site-packages/wandb/sdk/wandb_run.py", line 456, in wrapper_fn
    return func(self, *args, **kwargs)
  File "/home/vcivale/.local/lib/python3.10/site-packages/wandb/sdk/wandb_run.py", line 1566, in _console_raw_callback
    self._backend.interface.publish_output_raw(name, data)
  File "/home/vcivale/.local/lib/python3.10/site-packages/wandb/sdk/interface/interface.py", line 771, in publish_output_raw
    self._publish_output_raw(o)
  File "/home/vcivale/.local/lib/python3.10/site-packages/wandb/sdk/interface/interface_shared.py", line 38, in _publish_output_raw
    self._publish(rec)
  File "/home/vcivale/.local/lib/python3.10/site-packages/wandb/sdk/interface/interface_sock.py", line 39, in _publish
    self._sock_client.send_record_publish(record)
  File "/home/vcivale/.local/lib/python3.10/site-packages/wandb/sdk/lib/sock_client.py", line 170, in send_record_publish
    self.send_server_request(server_req)
  File "/home/vcivale/.local/lib/python3.10/site-packages/wandb/sdk/lib/sock_client.py", line 150, in send_server_request
    self._send_message(msg)
  File "/home/vcivale/.local/lib/python3.10/site-packages/wandb/sdk/lib/sock_client.py", line 147, in _send_message
    self._sendall_with_error_handle(header + data)
  File "/home/vcivale/.local/lib/python3.10/site-packages/wandb/sdk/lib/sock_client.py", line 126, in _sendall_with_error_handle
    sent = self._sock.send(data)
BrokenPipeError: [Errno 32] Broken pipe
2025-07-07 13:09:31,232 ERROR   MainThread:956308 [redirect.py:_on_write():664] [all runs] error in stdout callback
Traceback (most recent call last):
  File "/home/vcivale/.local/lib/python3.10/site-packages/IPython/core/events.py", line 82, in trigger
    func(*args, **kwargs)
  File "/home/vcivale/.local/lib/python3.10/site-packages/wandb/sdk/wandb_init.py", line 593, in _post_run_cell_hook
    self.backend.interface.publish_resume()
  File "/home/vcivale/.local/lib/python3.10/site-packages/wandb/sdk/interface/interface.py", line 787, in publish_resume
    self._publish_resume(resume)
  File "/home/vcivale/.local/lib/python3.10/site-packages/wandb/sdk/interface/interface_shared.py", line 294, in _publish_resume
    self._publish(rec)
  File "/home/vcivale/.local/lib/python3.10/site-packages/wandb/sdk/interface/interface_sock.py", line 39, in _publish
    self._sock_client.send_record_publish(record)
  File "/home/vcivale/.local/lib/python3.10/site-packages/wandb/sdk/lib/sock_client.py", line 170, in send_record_publish
    self.send_server_request(server_req)
  File "/home/vcivale/.local/lib/python3.10/site-packages/wandb/sdk/lib/sock_client.py", line 150, in send_server_request
    self._send_message(msg)
  File "/home/vcivale/.local/lib/python3.10/site-packages/wandb/sdk/lib/sock_client.py", line 147, in _send_message
    self._sendall_with_error_handle(header + data)
  File "/home/vcivale/.local/lib/python3.10/site-packages/wandb/sdk/lib/sock_client.py", line 126, in _sendall_with_error_handle
    sent = self._sock.send(data)
BrokenPipeError: [Errno 32] Broken pipe

During handling of the above exception, another exception occurred:

Traceback (most recent call last):
  File "/home/vcivale/.local/lib/python3.10/site-packages/wandb/sdk/lib/redirect.py", line 662, in _on_write
    cb(written_data)
  File "/home/vcivale/.local/lib/python3.10/site-packages/wandb/sdk/wandb_run.py", line 2379, in <lambda>
    lambda data: self._console_raw_callback("stdout", data),
  File "/home/vcivale/.local/lib/python3.10/site-packages/wandb/sdk/wandb_run.py", line 398, in wrapper
    return func(self, *args, **kwargs)
  File "/home/vcivale/.local/lib/python3.10/site-packages/wandb/sdk/wandb_run.py", line 456, in wrapper_fn
    return func(self, *args, **kwargs)
  File "/home/vcivale/.local/lib/python3.10/site-packages/wandb/sdk/wandb_run.py", line 1566, in _console_raw_callback
    self._backend.interface.publish_output_raw(name, data)
  File "/home/vcivale/.local/lib/python3.10/site-packages/wandb/sdk/interface/interface.py", line 771, in publish_output_raw
    self._publish_output_raw(o)
  File "/home/vcivale/.local/lib/python3.10/site-packages/wandb/sdk/interface/interface_shared.py", line 38, in _publish_output_raw
    self._publish(rec)
  File "/home/vcivale/.local/lib/python3.10/site-packages/wandb/sdk/interface/interface_sock.py", line 39, in _publish
    self._sock_client.send_record_publish(record)
  File "/home/vcivale/.local/lib/python3.10/site-packages/wandb/sdk/lib/sock_client.py", line 170, in send_record_publish
    self.send_server_request(server_req)
  File "/home/vcivale/.local/lib/python3.10/site-packages/wandb/sdk/lib/sock_client.py", line 150, in send_server_request
    self._send_message(msg)
  File "/home/vcivale/.local/lib/python3.10/site-packages/wandb/sdk/lib/sock_client.py", line 147, in _send_message
    self._sendall_with_error_handle(header + data)
  File "/home/vcivale/.local/lib/python3.10/site-packages/wandb/sdk/lib/sock_client.py", line 126, in _sendall_with_error_handle
    sent = self._sock.send(data)
BrokenPipeError: [Errno 32] Broken pipe
2025-07-07 13:09:31,313 INFO    MainThread:956308 [jupyter.py:save_ipynb():404] [no run ID] not saving jupyter notebook
2025-07-07 13:09:31,313 INFO    MainThread:956308 [wandb_init.py:_pre_run_cell_hook():581] [no run ID] pausing backend
2025-07-07 13:09:31,314 ERROR   MainThread:956308 [redirect.py:_on_write():664] [all runs] error in stdout callback
Traceback (most recent call last):
  File "/home/vcivale/.local/lib/python3.10/site-packages/IPython/core/events.py", line 82, in trigger
    func(*args, **kwargs)
  File "/home/vcivale/.local/lib/python3.10/site-packages/wandb/sdk/wandb_init.py", line 582, in _pre_run_cell_hook
    self.backend.interface.publish_pause()
  File "/home/vcivale/.local/lib/python3.10/site-packages/wandb/sdk/interface/interface.py", line 779, in publish_pause
    self._publish_pause(pause)
  File "/home/vcivale/.local/lib/python3.10/site-packages/wandb/sdk/interface/interface_shared.py", line 290, in _publish_pause
    self._publish(rec)
  File "/home/vcivale/.local/lib/python3.10/site-packages/wandb/sdk/interface/interface_sock.py", line 39, in _publish
    self._sock_client.send_record_publish(record)
  File "/home/vcivale/.local/lib/python3.10/site-packages/wandb/sdk/lib/sock_client.py", line 170, in send_record_publish
    self.send_server_request(server_req)
  File "/home/vcivale/.local/lib/python3.10/site-packages/wandb/sdk/lib/sock_client.py", line 150, in send_server_request
    self._send_message(msg)
  File "/home/vcivale/.local/lib/python3.10/site-packages/wandb/sdk/lib/sock_client.py", line 147, in _send_message
    self._sendall_with_error_handle(header + data)
  File "/home/vcivale/.local/lib/python3.10/site-packages/wandb/sdk/lib/sock_client.py", line 126, in _sendall_with_error_handle
    sent = self._sock.send(data)
BrokenPipeError: [Errno 32] Broken pipe

During handling of the above exception, another exception occurred:

Traceback (most recent call last):
  File "/home/vcivale/.local/lib/python3.10/site-packages/wandb/sdk/lib/redirect.py", line 662, in _on_write
    cb(written_data)
  File "/home/vcivale/.local/lib/python3.10/site-packages/wandb/sdk/wandb_run.py", line 2379, in <lambda>
    lambda data: self._console_raw_callback("stdout", data),
  File "/home/vcivale/.local/lib/python3.10/site-packages/wandb/sdk/wandb_run.py", line 398, in wrapper
    return func(self, *args, **kwargs)
  File "/home/vcivale/.local/lib/python3.10/site-packages/wandb/sdk/wandb_run.py", line 456, in wrapper_fn
    return func(self, *args, **kwargs)
  File "/home/vcivale/.local/lib/python3.10/site-packages/wandb/sdk/wandb_run.py", line 1566, in _console_raw_callback
    self._backend.interface.publish_output_raw(name, data)
  File "/home/vcivale/.local/lib/python3.10/site-packages/wandb/sdk/interface/interface.py", line 771, in publish_output_raw
    self._publish_output_raw(o)
  File "/home/vcivale/.local/lib/python3.10/site-packages/wandb/sdk/interface/interface_shared.py", line 38, in _publish_output_raw
    self._publish(rec)
  File "/home/vcivale/.local/lib/python3.10/site-packages/wandb/sdk/interface/interface_sock.py", line 39, in _publish
    self._sock_client.send_record_publish(record)
  File "/home/vcivale/.local/lib/python3.10/site-packages/wandb/sdk/lib/sock_client.py", line 170, in send_record_publish
    self.send_server_request(server_req)
  File "/home/vcivale/.local/lib/python3.10/site-packages/wandb/sdk/lib/sock_client.py", line 150, in send_server_request
    self._send_message(msg)
  File "/home/vcivale/.local/lib/python3.10/site-packages/wandb/sdk/lib/sock_client.py", line 147, in _send_message
    self._sendall_with_error_handle(header + data)
  File "/home/vcivale/.local/lib/python3.10/site-packages/wandb/sdk/lib/sock_client.py", line 126, in _sendall_with_error_handle
    sent = self._sock.send(data)
BrokenPipeError: [Errno 32] Broken pipe
2025-07-07 13:09:31,315 ERROR   MainThread:956308 [redirect.py:_on_write():664] [all runs] error in stdout callback
Traceback (most recent call last):
  File "/home/vcivale/.local/lib/python3.10/site-packages/IPython/core/events.py", line 82, in trigger
    func(*args, **kwargs)
  File "/home/vcivale/.local/lib/python3.10/site-packages/wandb/sdk/wandb_init.py", line 582, in _pre_run_cell_hook
    self.backend.interface.publish_pause()
  File "/home/vcivale/.local/lib/python3.10/site-packages/wandb/sdk/interface/interface.py", line 779, in publish_pause
    self._publish_pause(pause)
  File "/home/vcivale/.local/lib/python3.10/site-packages/wandb/sdk/interface/interface_shared.py", line 290, in _publish_pause
    self._publish(rec)
  File "/home/vcivale/.local/lib/python3.10/site-packages/wandb/sdk/interface/interface_sock.py", line 39, in _publish
    self._sock_client.send_record_publish(record)
  File "/home/vcivale/.local/lib/python3.10/site-packages/wandb/sdk/lib/sock_client.py", line 170, in send_record_publish
    self.send_server_request(server_req)
  File "/home/vcivale/.local/lib/python3.10/site-packages/wandb/sdk/lib/sock_client.py", line 150, in send_server_request
    self._send_message(msg)
  File "/home/vcivale/.local/lib/python3.10/site-packages/wandb/sdk/lib/sock_client.py", line 147, in _send_message
    self._sendall_with_error_handle(header + data)
  File "/home/vcivale/.local/lib/python3.10/site-packages/wandb/sdk/lib/sock_client.py", line 126, in _sendall_with_error_handle
    sent = self._sock.send(data)
BrokenPipeError: [Errno 32] Broken pipe

During handling of the above exception, another exception occurred:

Traceback (most recent call last):
  File "/home/vcivale/.local/lib/python3.10/site-packages/wandb/sdk/lib/redirect.py", line 662, in _on_write
    cb(written_data)
  File "/home/vcivale/.local/lib/python3.10/site-packages/wandb/sdk/wandb_run.py", line 2379, in <lambda>
    lambda data: self._console_raw_callback("stdout", data),
  File "/home/vcivale/.local/lib/python3.10/site-packages/wandb/sdk/wandb_run.py", line 398, in wrapper
    return func(self, *args, **kwargs)
  File "/home/vcivale/.local/lib/python3.10/site-packages/wandb/sdk/wandb_run.py", line 456, in wrapper_fn
    return func(self, *args, **kwargs)
  File "/home/vcivale/.local/lib/python3.10/site-packages/wandb/sdk/wandb_run.py", line 1566, in _console_raw_callback
    self._backend.interface.publish_output_raw(name, data)
  File "/home/vcivale/.local/lib/python3.10/site-packages/wandb/sdk/interface/interface.py", line 771, in publish_output_raw
    self._publish_output_raw(o)
  File "/home/vcivale/.local/lib/python3.10/site-packages/wandb/sdk/interface/interface_shared.py", line 38, in _publish_output_raw
    self._publish(rec)
  File "/home/vcivale/.local/lib/python3.10/site-packages/wandb/sdk/interface/interface_sock.py", line 39, in _publish
    self._sock_client.send_record_publish(record)
  File "/home/vcivale/.local/lib/python3.10/site-packages/wandb/sdk/lib/sock_client.py", line 170, in send_record_publish
    self.send_server_request(server_req)
  File "/home/vcivale/.local/lib/python3.10/site-packages/wandb/sdk/lib/sock_client.py", line 150, in send_server_request
    self._send_message(msg)
  File "/home/vcivale/.local/lib/python3.10/site-packages/wandb/sdk/lib/sock_client.py", line 147, in _send_message
    self._sendall_with_error_handle(header + data)
  File "/home/vcivale/.local/lib/python3.10/site-packages/wandb/sdk/lib/sock_client.py", line 126, in _sendall_with_error_handle
    sent = self._sock.send(data)
BrokenPipeError: [Errno 32] Broken pipe
2025-07-07 13:09:31,375 ERROR   MainThread:956308 [redirect.py:_on_write():664] [all runs] error in stdout callback
Traceback (most recent call last):
  File "/home/vcivale/.local/lib/python3.10/site-packages/wandb/sdk/lib/redirect.py", line 662, in _on_write
    cb(written_data)
  File "/home/vcivale/.local/lib/python3.10/site-packages/wandb/sdk/wandb_run.py", line 2379, in <lambda>
    lambda data: self._console_raw_callback("stdout", data),
  File "/home/vcivale/.local/lib/python3.10/site-packages/wandb/sdk/wandb_run.py", line 398, in wrapper
    return func(self, *args, **kwargs)
  File "/home/vcivale/.local/lib/python3.10/site-packages/wandb/sdk/wandb_run.py", line 456, in wrapper_fn
    return func(self, *args, **kwargs)
  File "/home/vcivale/.local/lib/python3.10/site-packages/wandb/sdk/wandb_run.py", line 1566, in _console_raw_callback
    self._backend.interface.publish_output_raw(name, data)
  File "/home/vcivale/.local/lib/python3.10/site-packages/wandb/sdk/interface/interface.py", line 771, in publish_output_raw
    self._publish_output_raw(o)
  File "/home/vcivale/.local/lib/python3.10/site-packages/wandb/sdk/interface/interface_shared.py", line 38, in _publish_output_raw
    self._publish(rec)
  File "/home/vcivale/.local/lib/python3.10/site-packages/wandb/sdk/interface/interface_sock.py", line 39, in _publish
    self._sock_client.send_record_publish(record)
  File "/home/vcivale/.local/lib/python3.10/site-packages/wandb/sdk/lib/sock_client.py", line 170, in send_record_publish
    self.send_server_request(server_req)
  File "/home/vcivale/.local/lib/python3.10/site-packages/wandb/sdk/lib/sock_client.py", line 150, in send_server_request
    self._send_message(msg)
  File "/home/vcivale/.local/lib/python3.10/site-packages/wandb/sdk/lib/sock_client.py", line 147, in _send_message
    self._sendall_with_error_handle(header + data)
  File "/home/vcivale/.local/lib/python3.10/site-packages/wandb/sdk/lib/sock_client.py", line 126, in _sendall_with_error_handle
    sent = self._sock.send(data)
BrokenPipeError: [Errno 32] Broken pipe
2025-07-07 13:09:31,376 ERROR   MainThread:956308 [redirect.py:_on_write():664] [all runs] error in stdout callback
Traceback (most recent call last):
  File "/home/vcivale/.local/lib/python3.10/site-packages/wandb/sdk/lib/redirect.py", line 662, in _on_write
    cb(written_data)
  File "/home/vcivale/.local/lib/python3.10/site-packages/wandb/sdk/wandb_run.py", line 2379, in <lambda>
    lambda data: self._console_raw_callback("stdout", data),
  File "/home/vcivale/.local/lib/python3.10/site-packages/wandb/sdk/wandb_run.py", line 398, in wrapper
    return func(self, *args, **kwargs)
  File "/home/vcivale/.local/lib/python3.10/site-packages/wandb/sdk/wandb_run.py", line 456, in wrapper_fn
    return func(self, *args, **kwargs)
  File "/home/vcivale/.local/lib/python3.10/site-packages/wandb/sdk/wandb_run.py", line 1566, in _console_raw_callback
    self._backend.interface.publish_output_raw(name, data)
  File "/home/vcivale/.local/lib/python3.10/site-packages/wandb/sdk/interface/interface.py", line 771, in publish_output_raw
    self._publish_output_raw(o)
  File "/home/vcivale/.local/lib/python3.10/site-packages/wandb/sdk/interface/interface_shared.py", line 38, in _publish_output_raw
    self._publish(rec)
  File "/home/vcivale/.local/lib/python3.10/site-packages/wandb/sdk/interface/interface_sock.py", line 39, in _publish
    self._sock_client.send_record_publish(record)
  File "/home/vcivale/.local/lib/python3.10/site-packages/wandb/sdk/lib/sock_client.py", line 170, in send_record_publish
    self.send_server_request(server_req)
  File "/home/vcivale/.local/lib/python3.10/site-packages/wandb/sdk/lib/sock_client.py", line 150, in send_server_request
    self._send_message(msg)
  File "/home/vcivale/.local/lib/python3.10/site-packages/wandb/sdk/lib/sock_client.py", line 147, in _send_message
    self._sendall_with_error_handle(header + data)
  File "/home/vcivale/.local/lib/python3.10/site-packages/wandb/sdk/lib/sock_client.py", line 126, in _sendall_with_error_handle
    sent = self._sock.send(data)
BrokenPipeError: [Errno 32] Broken pipe
2025-07-07 13:09:31,376 INFO    MainThread:956308 [wandb_init.py:_post_run_cell_hook():592] [no run ID] resuming backend
2025-07-07 13:09:31,377 ERROR   MainThread:956308 [redirect.py:_on_write():664] [all runs] error in stdout callback
Traceback (most recent call last):
  File "/home/vcivale/.local/lib/python3.10/site-packages/IPython/core/events.py", line 82, in trigger
    func(*args, **kwargs)
  File "/home/vcivale/.local/lib/python3.10/site-packages/wandb/sdk/wandb_init.py", line 593, in _post_run_cell_hook
    self.backend.interface.publish_resume()
  File "/home/vcivale/.local/lib/python3.10/site-packages/wandb/sdk/interface/interface.py", line 787, in publish_resume
    self._publish_resume(resume)
  File "/home/vcivale/.local/lib/python3.10/site-packages/wandb/sdk/interface/interface_shared.py", line 294, in _publish_resume
    self._publish(rec)
  File "/home/vcivale/.local/lib/python3.10/site-packages/wandb/sdk/interface/interface_sock.py", line 39, in _publish
    self._sock_client.send_record_publish(record)
  File "/home/vcivale/.local/lib/python3.10/site-packages/wandb/sdk/lib/sock_client.py", line 170, in send_record_publish
    self.send_server_request(server_req)
  File "/home/vcivale/.local/lib/python3.10/site-packages/wandb/sdk/lib/sock_client.py", line 150, in send_server_request
    self._send_message(msg)
  File "/home/vcivale/.local/lib/python3.10/site-packages/wandb/sdk/lib/sock_client.py", line 147, in _send_message
    self._sendall_with_error_handle(header + data)
  File "/home/vcivale/.local/lib/python3.10/site-packages/wandb/sdk/lib/sock_client.py", line 126, in _sendall_with_error_handle
    sent = self._sock.send(data)
BrokenPipeError: [Errno 32] Broken pipe

During handling of the above exception, another exception occurred:

Traceback (most recent call last):
  File "/home/vcivale/.local/lib/python3.10/site-packages/wandb/sdk/lib/redirect.py", line 662, in _on_write
    cb(written_data)
  File "/home/vcivale/.local/lib/python3.10/site-packages/wandb/sdk/wandb_run.py", line 2379, in <lambda>
    lambda data: self._console_raw_callback("stdout", data),
  File "/home/vcivale/.local/lib/python3.10/site-packages/wandb/sdk/wandb_run.py", line 398, in wrapper
    return func(self, *args, **kwargs)
  File "/home/vcivale/.local/lib/python3.10/site-packages/wandb/sdk/wandb_run.py", line 456, in wrapper_fn
    return func(self, *args, **kwargs)
  File "/home/vcivale/.local/lib/python3.10/site-packages/wandb/sdk/wandb_run.py", line 1566, in _console_raw_callback
    self._backend.interface.publish_output_raw(name, data)
  File "/home/vcivale/.local/lib/python3.10/site-packages/wandb/sdk/interface/interface.py", line 771, in publish_output_raw
    self._publish_output_raw(o)
  File "/home/vcivale/.local/lib/python3.10/site-packages/wandb/sdk/interface/interface_shared.py", line 38, in _publish_output_raw
    self._publish(rec)
  File "/home/vcivale/.local/lib/python3.10/site-packages/wandb/sdk/interface/interface_sock.py", line 39, in _publish
    self._sock_client.send_record_publish(record)
  File "/home/vcivale/.local/lib/python3.10/site-packages/wandb/sdk/lib/sock_client.py", line 170, in send_record_publish
    self.send_server_request(server_req)
  File "/home/vcivale/.local/lib/python3.10/site-packages/wandb/sdk/lib/sock_client.py", line 150, in send_server_request
    self._send_message(msg)
  File "/home/vcivale/.local/lib/python3.10/site-packages/wandb/sdk/lib/sock_client.py", line 147, in _send_message
    self._sendall_with_error_handle(header + data)
  File "/home/vcivale/.local/lib/python3.10/site-packages/wandb/sdk/lib/sock_client.py", line 126, in _sendall_with_error_handle
    sent = self._sock.send(data)
BrokenPipeError: [Errno 32] Broken pipe
2025-07-07 13:09:31,377 ERROR   MainThread:956308 [redirect.py:_on_write():664] [all runs] error in stdout callback
Traceback (most recent call last):
  File "/home/vcivale/.local/lib/python3.10/site-packages/IPython/core/events.py", line 82, in trigger
    func(*args, **kwargs)
  File "/home/vcivale/.local/lib/python3.10/site-packages/wandb/sdk/wandb_init.py", line 593, in _post_run_cell_hook
    self.backend.interface.publish_resume()
  File "/home/vcivale/.local/lib/python3.10/site-packages/wandb/sdk/interface/interface.py", line 787, in publish_resume
    self._publish_resume(resume)
  File "/home/vcivale/.local/lib/python3.10/site-packages/wandb/sdk/interface/interface_shared.py", line 294, in _publish_resume
    self._publish(rec)
  File "/home/vcivale/.local/lib/python3.10/site-packages/wandb/sdk/interface/interface_sock.py", line 39, in _publish
    self._sock_client.send_record_publish(record)
  File "/home/vcivale/.local/lib/python3.10/site-packages/wandb/sdk/lib/sock_client.py", line 170, in send_record_publish
    self.send_server_request(server_req)
  File "/home/vcivale/.local/lib/python3.10/site-packages/wandb/sdk/lib/sock_client.py", line 150, in send_server_request
    self._send_message(msg)
  File "/home/vcivale/.local/lib/python3.10/site-packages/wandb/sdk/lib/sock_client.py", line 147, in _send_message
    self._sendall_with_error_handle(header + data)
  File "/home/vcivale/.local/lib/python3.10/site-packages/wandb/sdk/lib/sock_client.py", line 126, in _sendall_with_error_handle
    sent = self._sock.send(data)
BrokenPipeError: [Errno 32] Broken pipe

During handling of the above exception, another exception occurred:

Traceback (most recent call last):
  File "/home/vcivale/.local/lib/python3.10/site-packages/wandb/sdk/lib/redirect.py", line 662, in _on_write
    cb(written_data)
  File "/home/vcivale/.local/lib/python3.10/site-packages/wandb/sdk/wandb_run.py", line 2379, in <lambda>
    lambda data: self._console_raw_callback("stdout", data),
  File "/home/vcivale/.local/lib/python3.10/site-packages/wandb/sdk/wandb_run.py", line 398, in wrapper
    return func(self, *args, **kwargs)
  File "/home/vcivale/.local/lib/python3.10/site-packages/wandb/sdk/wandb_run.py", line 456, in wrapper_fn
    return func(self, *args, **kwargs)
  File "/home/vcivale/.local/lib/python3.10/site-packages/wandb/sdk/wandb_run.py", line 1566, in _console_raw_callback
    self._backend.interface.publish_output_raw(name, data)
  File "/home/vcivale/.local/lib/python3.10/site-packages/wandb/sdk/interface/interface.py", line 771, in publish_output_raw
    self._publish_output_raw(o)
  File "/home/vcivale/.local/lib/python3.10/site-packages/wandb/sdk/interface/interface_shared.py", line 38, in _publish_output_raw
    self._publish(rec)
  File "/home/vcivale/.local/lib/python3.10/site-packages/wandb/sdk/interface/interface_sock.py", line 39, in _publish
    self._sock_client.send_record_publish(record)
  File "/home/vcivale/.local/lib/python3.10/site-packages/wandb/sdk/lib/sock_client.py", line 170, in send_record_publish
    self.send_server_request(server_req)
  File "/home/vcivale/.local/lib/python3.10/site-packages/wandb/sdk/lib/sock_client.py", line 150, in send_server_request
    self._send_message(msg)
  File "/home/vcivale/.local/lib/python3.10/site-packages/wandb/sdk/lib/sock_client.py", line 147, in _send_message
    self._sendall_with_error_handle(header + data)
  File "/home/vcivale/.local/lib/python3.10/site-packages/wandb/sdk/lib/sock_client.py", line 126, in _sendall_with_error_handle
    sent = self._sock.send(data)
BrokenPipeError: [Errno 32] Broken pipe
2025-07-07 13:09:31,458 INFO    MainThread:956308 [jupyter.py:save_ipynb():404] [no run ID] not saving jupyter notebook
2025-07-07 13:09:31,458 INFO    MainThread:956308 [wandb_init.py:_pre_run_cell_hook():581] [no run ID] pausing backend
2025-07-07 13:09:31,458 ERROR   MainThread:956308 [redirect.py:_on_write():664] [all runs] error in stdout callback
Traceback (most recent call last):
  File "/home/vcivale/.local/lib/python3.10/site-packages/IPython/core/events.py", line 82, in trigger
    func(*args, **kwargs)
  File "/home/vcivale/.local/lib/python3.10/site-packages/wandb/sdk/wandb_init.py", line 582, in _pre_run_cell_hook
    self.backend.interface.publish_pause()
  File "/home/vcivale/.local/lib/python3.10/site-packages/wandb/sdk/interface/interface.py", line 779, in publish_pause
    self._publish_pause(pause)
  File "/home/vcivale/.local/lib/python3.10/site-packages/wandb/sdk/interface/interface_shared.py", line 290, in _publish_pause
    self._publish(rec)
  File "/home/vcivale/.local/lib/python3.10/site-packages/wandb/sdk/interface/interface_sock.py", line 39, in _publish
    self._sock_client.send_record_publish(record)
  File "/home/vcivale/.local/lib/python3.10/site-packages/wandb/sdk/lib/sock_client.py", line 170, in send_record_publish
    self.send_server_request(server_req)
  File "/home/vcivale/.local/lib/python3.10/site-packages/wandb/sdk/lib/sock_client.py", line 150, in send_server_request
    self._send_message(msg)
  File "/home/vcivale/.local/lib/python3.10/site-packages/wandb/sdk/lib/sock_client.py", line 147, in _send_message
    self._sendall_with_error_handle(header + data)
  File "/home/vcivale/.local/lib/python3.10/site-packages/wandb/sdk/lib/sock_client.py", line 126, in _sendall_with_error_handle
    sent = self._sock.send(data)
BrokenPipeError: [Errno 32] Broken pipe

During handling of the above exception, another exception occurred:

Traceback (most recent call last):
  File "/home/vcivale/.local/lib/python3.10/site-packages/wandb/sdk/lib/redirect.py", line 662, in _on_write
    cb(written_data)
  File "/home/vcivale/.local/lib/python3.10/site-packages/wandb/sdk/wandb_run.py", line 2379, in <lambda>
    lambda data: self._console_raw_callback("stdout", data),
  File "/home/vcivale/.local/lib/python3.10/site-packages/wandb/sdk/wandb_run.py", line 398, in wrapper
    return func(self, *args, **kwargs)
  File "/home/vcivale/.local/lib/python3.10/site-packages/wandb/sdk/wandb_run.py", line 456, in wrapper_fn
    return func(self, *args, **kwargs)
  File "/home/vcivale/.local/lib/python3.10/site-packages/wandb/sdk/wandb_run.py", line 1566, in _console_raw_callback
    self._backend.interface.publish_output_raw(name, data)
  File "/home/vcivale/.local/lib/python3.10/site-packages/wandb/sdk/interface/interface.py", line 771, in publish_output_raw
    self._publish_output_raw(o)
  File "/home/vcivale/.local/lib/python3.10/site-packages/wandb/sdk/interface/interface_shared.py", line 38, in _publish_output_raw
    self._publish(rec)
  File "/home/vcivale/.local/lib/python3.10/site-packages/wandb/sdk/interface/interface_sock.py", line 39, in _publish
    self._sock_client.send_record_publish(record)
  File "/home/vcivale/.local/lib/python3.10/site-packages/wandb/sdk/lib/sock_client.py", line 170, in send_record_publish
    self.send_server_request(server_req)
  File "/home/vcivale/.local/lib/python3.10/site-packages/wandb/sdk/lib/sock_client.py", line 150, in send_server_request
    self._send_message(msg)
  File "/home/vcivale/.local/lib/python3.10/site-packages/wandb/sdk/lib/sock_client.py", line 147, in _send_message
    self._sendall_with_error_handle(header + data)
  File "/home/vcivale/.local/lib/python3.10/site-packages/wandb/sdk/lib/sock_client.py", line 126, in _sendall_with_error_handle
    sent = self._sock.send(data)
BrokenPipeError: [Errno 32] Broken pipe
2025-07-07 13:09:31,459 ERROR   MainThread:956308 [redirect.py:_on_write():664] [all runs] error in stdout callback
Traceback (most recent call last):
  File "/home/vcivale/.local/lib/python3.10/site-packages/IPython/core/events.py", line 82, in trigger
    func(*args, **kwargs)
  File "/home/vcivale/.local/lib/python3.10/site-packages/wandb/sdk/wandb_init.py", line 582, in _pre_run_cell_hook
    self.backend.interface.publish_pause()
  File "/home/vcivale/.local/lib/python3.10/site-packages/wandb/sdk/interface/interface.py", line 779, in publish_pause
    self._publish_pause(pause)
  File "/home/vcivale/.local/lib/python3.10/site-packages/wandb/sdk/interface/interface_shared.py", line 290, in _publish_pause
    self._publish(rec)
  File "/home/vcivale/.local/lib/python3.10/site-packages/wandb/sdk/interface/interface_sock.py", line 39, in _publish
    self._sock_client.send_record_publish(record)
  File "/home/vcivale/.local/lib/python3.10/site-packages/wandb/sdk/lib/sock_client.py", line 170, in send_record_publish
    self.send_server_request(server_req)
  File "/home/vcivale/.local/lib/python3.10/site-packages/wandb/sdk/lib/sock_client.py", line 150, in send_server_request
    self._send_message(msg)
  File "/home/vcivale/.local/lib/python3.10/site-packages/wandb/sdk/lib/sock_client.py", line 147, in _send_message
    self._sendall_with_error_handle(header + data)
  File "/home/vcivale/.local/lib/python3.10/site-packages/wandb/sdk/lib/sock_client.py", line 126, in _sendall_with_error_handle
    sent = self._sock.send(data)
BrokenPipeError: [Errno 32] Broken pipe

During handling of the above exception, another exception occurred:

Traceback (most recent call last):
  File "/home/vcivale/.local/lib/python3.10/site-packages/wandb/sdk/lib/redirect.py", line 662, in _on_write
    cb(written_data)
  File "/home/vcivale/.local/lib/python3.10/site-packages/wandb/sdk/wandb_run.py", line 2379, in <lambda>
    lambda data: self._console_raw_callback("stdout", data),
  File "/home/vcivale/.local/lib/python3.10/site-packages/wandb/sdk/wandb_run.py", line 398, in wrapper
    return func(self, *args, **kwargs)
  File "/home/vcivale/.local/lib/python3.10/site-packages/wandb/sdk/wandb_run.py", line 456, in wrapper_fn
    return func(self, *args, **kwargs)
  File "/home/vcivale/.local/lib/python3.10/site-packages/wandb/sdk/wandb_run.py", line 1566, in _console_raw_callback
    self._backend.interface.publish_output_raw(name, data)
  File "/home/vcivale/.local/lib/python3.10/site-packages/wandb/sdk/interface/interface.py", line 771, in publish_output_raw
    self._publish_output_raw(o)
  File "/home/vcivale/.local/lib/python3.10/site-packages/wandb/sdk/interface/interface_shared.py", line 38, in _publish_output_raw
    self._publish(rec)
  File "/home/vcivale/.local/lib/python3.10/site-packages/wandb/sdk/interface/interface_sock.py", line 39, in _publish
    self._sock_client.send_record_publish(record)
  File "/home/vcivale/.local/lib/python3.10/site-packages/wandb/sdk/lib/sock_client.py", line 170, in send_record_publish
    self.send_server_request(server_req)
  File "/home/vcivale/.local/lib/python3.10/site-packages/wandb/sdk/lib/sock_client.py", line 150, in send_server_request
    self._send_message(msg)
  File "/home/vcivale/.local/lib/python3.10/site-packages/wandb/sdk/lib/sock_client.py", line 147, in _send_message
    self._sendall_with_error_handle(header + data)
  File "/home/vcivale/.local/lib/python3.10/site-packages/wandb/sdk/lib/sock_client.py", line 126, in _sendall_with_error_handle
    sent = self._sock.send(data)
BrokenPipeError: [Errno 32] Broken pipe
2025-07-07 13:09:31,520 INFO    MainThread:956308 [wandb_init.py:_post_run_cell_hook():592] [no run ID] resuming backend
2025-07-07 13:09:31,520 ERROR   MainThread:956308 [redirect.py:_on_write():664] [all runs] error in stdout callback
Traceback (most recent call last):
  File "/home/vcivale/.local/lib/python3.10/site-packages/IPython/core/events.py", line 82, in trigger
    func(*args, **kwargs)
  File "/home/vcivale/.local/lib/python3.10/site-packages/wandb/sdk/wandb_init.py", line 593, in _post_run_cell_hook
    self.backend.interface.publish_resume()
  File "/home/vcivale/.local/lib/python3.10/site-packages/wandb/sdk/interface/interface.py", line 787, in publish_resume
    self._publish_resume(resume)
  File "/home/vcivale/.local/lib/python3.10/site-packages/wandb/sdk/interface/interface_shared.py", line 294, in _publish_resume
    self._publish(rec)
  File "/home/vcivale/.local/lib/python3.10/site-packages/wandb/sdk/interface/interface_sock.py", line 39, in _publish
    self._sock_client.send_record_publish(record)
  File "/home/vcivale/.local/lib/python3.10/site-packages/wandb/sdk/lib/sock_client.py", line 170, in send_record_publish
    self.send_server_request(server_req)
  File "/home/vcivale/.local/lib/python3.10/site-packages/wandb/sdk/lib/sock_client.py", line 150, in send_server_request
    self._send_message(msg)
  File "/home/vcivale/.local/lib/python3.10/site-packages/wandb/sdk/lib/sock_client.py", line 147, in _send_message
    self._sendall_with_error_handle(header + data)
  File "/home/vcivale/.local/lib/python3.10/site-packages/wandb/sdk/lib/sock_client.py", line 126, in _sendall_with_error_handle
    sent = self._sock.send(data)
BrokenPipeError: [Errno 32] Broken pipe

During handling of the above exception, another exception occurred:

Traceback (most recent call last):
  File "/home/vcivale/.local/lib/python3.10/site-packages/wandb/sdk/lib/redirect.py", line 662, in _on_write
    cb(written_data)
  File "/home/vcivale/.local/lib/python3.10/site-packages/wandb/sdk/wandb_run.py", line 2379, in <lambda>
    lambda data: self._console_raw_callback("stdout", data),
  File "/home/vcivale/.local/lib/python3.10/site-packages/wandb/sdk/wandb_run.py", line 398, in wrapper
    return func(self, *args, **kwargs)
  File "/home/vcivale/.local/lib/python3.10/site-packages/wandb/sdk/wandb_run.py", line 456, in wrapper_fn
    return func(self, *args, **kwargs)
  File "/home/vcivale/.local/lib/python3.10/site-packages/wandb/sdk/wandb_run.py", line 1566, in _console_raw_callback
    self._backend.interface.publish_output_raw(name, data)
  File "/home/vcivale/.local/lib/python3.10/site-packages/wandb/sdk/interface/interface.py", line 771, in publish_output_raw
    self._publish_output_raw(o)
  File "/home/vcivale/.local/lib/python3.10/site-packages/wandb/sdk/interface/interface_shared.py", line 38, in _publish_output_raw
    self._publish(rec)
  File "/home/vcivale/.local/lib/python3.10/site-packages/wandb/sdk/interface/interface_sock.py", line 39, in _publish
    self._sock_client.send_record_publish(record)
  File "/home/vcivale/.local/lib/python3.10/site-packages/wandb/sdk/lib/sock_client.py", line 170, in send_record_publish
    self.send_server_request(server_req)
  File "/home/vcivale/.local/lib/python3.10/site-packages/wandb/sdk/lib/sock_client.py", line 150, in send_server_request
    self._send_message(msg)
  File "/home/vcivale/.local/lib/python3.10/site-packages/wandb/sdk/lib/sock_client.py", line 147, in _send_message
    self._sendall_with_error_handle(header + data)
  File "/home/vcivale/.local/lib/python3.10/site-packages/wandb/sdk/lib/sock_client.py", line 126, in _sendall_with_error_handle
    sent = self._sock.send(data)
BrokenPipeError: [Errno 32] Broken pipe
2025-07-07 13:09:31,521 ERROR   MainThread:956308 [redirect.py:_on_write():664] [all runs] error in stdout callback
Traceback (most recent call last):
  File "/home/vcivale/.local/lib/python3.10/site-packages/IPython/core/events.py", line 82, in trigger
    func(*args, **kwargs)
  File "/home/vcivale/.local/lib/python3.10/site-packages/wandb/sdk/wandb_init.py", line 593, in _post_run_cell_hook
    self.backend.interface.publish_resume()
  File "/home/vcivale/.local/lib/python3.10/site-packages/wandb/sdk/interface/interface.py", line 787, in publish_resume
    self._publish_resume(resume)
  File "/home/vcivale/.local/lib/python3.10/site-packages/wandb/sdk/interface/interface_shared.py", line 294, in _publish_resume
    self._publish(rec)
  File "/home/vcivale/.local/lib/python3.10/site-packages/wandb/sdk/interface/interface_sock.py", line 39, in _publish
    self._sock_client.send_record_publish(record)
  File "/home/vcivale/.local/lib/python3.10/site-packages/wandb/sdk/lib/sock_client.py", line 170, in send_record_publish
    self.send_server_request(server_req)
  File "/home/vcivale/.local/lib/python3.10/site-packages/wandb/sdk/lib/sock_client.py", line 150, in send_server_request
    self._send_message(msg)
  File "/home/vcivale/.local/lib/python3.10/site-packages/wandb/sdk/lib/sock_client.py", line 147, in _send_message
    self._sendall_with_error_handle(header + data)
  File "/home/vcivale/.local/lib/python3.10/site-packages/wandb/sdk/lib/sock_client.py", line 126, in _sendall_with_error_handle
    sent = self._sock.send(data)
BrokenPipeError: [Errno 32] Broken pipe

During handling of the above exception, another exception occurred:

Traceback (most recent call last):
  File "/home/vcivale/.local/lib/python3.10/site-packages/wandb/sdk/lib/redirect.py", line 662, in _on_write
    cb(written_data)
  File "/home/vcivale/.local/lib/python3.10/site-packages/wandb/sdk/wandb_run.py", line 2379, in <lambda>
    lambda data: self._console_raw_callback("stdout", data),
  File "/home/vcivale/.local/lib/python3.10/site-packages/wandb/sdk/wandb_run.py", line 398, in wrapper
    return func(self, *args, **kwargs)
  File "/home/vcivale/.local/lib/python3.10/site-packages/wandb/sdk/wandb_run.py", line 456, in wrapper_fn
    return func(self, *args, **kwargs)
  File "/home/vcivale/.local/lib/python3.10/site-packages/wandb/sdk/wandb_run.py", line 1566, in _console_raw_callback
    self._backend.interface.publish_output_raw(name, data)
  File "/home/vcivale/.local/lib/python3.10/site-packages/wandb/sdk/interface/interface.py", line 771, in publish_output_raw
    self._publish_output_raw(o)
  File "/home/vcivale/.local/lib/python3.10/site-packages/wandb/sdk/interface/interface_shared.py", line 38, in _publish_output_raw
    self._publish(rec)
  File "/home/vcivale/.local/lib/python3.10/site-packages/wandb/sdk/interface/interface_sock.py", line 39, in _publish
    self._sock_client.send_record_publish(record)
  File "/home/vcivale/.local/lib/python3.10/site-packages/wandb/sdk/lib/sock_client.py", line 170, in send_record_publish
    self.send_server_request(server_req)
  File "/home/vcivale/.local/lib/python3.10/site-packages/wandb/sdk/lib/sock_client.py", line 150, in send_server_request
    self._send_message(msg)
  File "/home/vcivale/.local/lib/python3.10/site-packages/wandb/sdk/lib/sock_client.py", line 147, in _send_message
    self._sendall_with_error_handle(header + data)
  File "/home/vcivale/.local/lib/python3.10/site-packages/wandb/sdk/lib/sock_client.py", line 126, in _sendall_with_error_handle
    sent = self._sock.send(data)
BrokenPipeError: [Errno 32] Broken pipe
2025-07-07 13:09:31,606 INFO    MainThread:956308 [jupyter.py:save_ipynb():404] [no run ID] not saving jupyter notebook
2025-07-07 13:09:31,606 INFO    MainThread:956308 [wandb_init.py:_pre_run_cell_hook():581] [no run ID] pausing backend
2025-07-07 13:09:31,606 ERROR   MainThread:956308 [redirect.py:_on_write():664] [all runs] error in stdout callback
Traceback (most recent call last):
  File "/home/vcivale/.local/lib/python3.10/site-packages/IPython/core/events.py", line 82, in trigger
    func(*args, **kwargs)
  File "/home/vcivale/.local/lib/python3.10/site-packages/wandb/sdk/wandb_init.py", line 582, in _pre_run_cell_hook
    self.backend.interface.publish_pause()
  File "/home/vcivale/.local/lib/python3.10/site-packages/wandb/sdk/interface/interface.py", line 779, in publish_pause
    self._publish_pause(pause)
  File "/home/vcivale/.local/lib/python3.10/site-packages/wandb/sdk/interface/interface_shared.py", line 290, in _publish_pause
    self._publish(rec)
  File "/home/vcivale/.local/lib/python3.10/site-packages/wandb/sdk/interface/interface_sock.py", line 39, in _publish
    self._sock_client.send_record_publish(record)
  File "/home/vcivale/.local/lib/python3.10/site-packages/wandb/sdk/lib/sock_client.py", line 170, in send_record_publish
    self.send_server_request(server_req)
  File "/home/vcivale/.local/lib/python3.10/site-packages/wandb/sdk/lib/sock_client.py", line 150, in send_server_request
    self._send_message(msg)
  File "/home/vcivale/.local/lib/python3.10/site-packages/wandb/sdk/lib/sock_client.py", line 147, in _send_message
    self._sendall_with_error_handle(header + data)
  File "/home/vcivale/.local/lib/python3.10/site-packages/wandb/sdk/lib/sock_client.py", line 126, in _sendall_with_error_handle
    sent = self._sock.send(data)
BrokenPipeError: [Errno 32] Broken pipe

During handling of the above exception, another exception occurred:

Traceback (most recent call last):
  File "/home/vcivale/.local/lib/python3.10/site-packages/wandb/sdk/lib/redirect.py", line 662, in _on_write
    cb(written_data)
  File "/home/vcivale/.local/lib/python3.10/site-packages/wandb/sdk/wandb_run.py", line 2379, in <lambda>
    lambda data: self._console_raw_callback("stdout", data),
  File "/home/vcivale/.local/lib/python3.10/site-packages/wandb/sdk/wandb_run.py", line 398, in wrapper
    return func(self, *args, **kwargs)
  File "/home/vcivale/.local/lib/python3.10/site-packages/wandb/sdk/wandb_run.py", line 456, in wrapper_fn
    return func(self, *args, **kwargs)
  File "/home/vcivale/.local/lib/python3.10/site-packages/wandb/sdk/wandb_run.py", line 1566, in _console_raw_callback
    self._backend.interface.publish_output_raw(name, data)
  File "/home/vcivale/.local/lib/python3.10/site-packages/wandb/sdk/interface/interface.py", line 771, in publish_output_raw
    self._publish_output_raw(o)
  File "/home/vcivale/.local/lib/python3.10/site-packages/wandb/sdk/interface/interface_shared.py", line 38, in _publish_output_raw
    self._publish(rec)
  File "/home/vcivale/.local/lib/python3.10/site-packages/wandb/sdk/interface/interface_sock.py", line 39, in _publish
    self._sock_client.send_record_publish(record)
  File "/home/vcivale/.local/lib/python3.10/site-packages/wandb/sdk/lib/sock_client.py", line 170, in send_record_publish
    self.send_server_request(server_req)
  File "/home/vcivale/.local/lib/python3.10/site-packages/wandb/sdk/lib/sock_client.py", line 150, in send_server_request
    self._send_message(msg)
  File "/home/vcivale/.local/lib/python3.10/site-packages/wandb/sdk/lib/sock_client.py", line 147, in _send_message
    self._sendall_with_error_handle(header + data)
  File "/home/vcivale/.local/lib/python3.10/site-packages/wandb/sdk/lib/sock_client.py", line 126, in _sendall_with_error_handle
    sent = self._sock.send(data)
BrokenPipeError: [Errno 32] Broken pipe
2025-07-07 13:09:31,608 ERROR   MainThread:956308 [redirect.py:_on_write():664] [all runs] error in stdout callback
Traceback (most recent call last):
  File "/home/vcivale/.local/lib/python3.10/site-packages/IPython/core/events.py", line 82, in trigger
    func(*args, **kwargs)
  File "/home/vcivale/.local/lib/python3.10/site-packages/wandb/sdk/wandb_init.py", line 582, in _pre_run_cell_hook
    self.backend.interface.publish_pause()
  File "/home/vcivale/.local/lib/python3.10/site-packages/wandb/sdk/interface/interface.py", line 779, in publish_pause
    self._publish_pause(pause)
  File "/home/vcivale/.local/lib/python3.10/site-packages/wandb/sdk/interface/interface_shared.py", line 290, in _publish_pause
    self._publish(rec)
  File "/home/vcivale/.local/lib/python3.10/site-packages/wandb/sdk/interface/interface_sock.py", line 39, in _publish
    self._sock_client.send_record_publish(record)
  File "/home/vcivale/.local/lib/python3.10/site-packages/wandb/sdk/lib/sock_client.py", line 170, in send_record_publish
    self.send_server_request(server_req)
  File "/home/vcivale/.local/lib/python3.10/site-packages/wandb/sdk/lib/sock_client.py", line 150, in send_server_request
    self._send_message(msg)
  File "/home/vcivale/.local/lib/python3.10/site-packages/wandb/sdk/lib/sock_client.py", line 147, in _send_message
    self._sendall_with_error_handle(header + data)
  File "/home/vcivale/.local/lib/python3.10/site-packages/wandb/sdk/lib/sock_client.py", line 126, in _sendall_with_error_handle
    sent = self._sock.send(data)
BrokenPipeError: [Errno 32] Broken pipe

During handling of the above exception, another exception occurred:

Traceback (most recent call last):
  File "/home/vcivale/.local/lib/python3.10/site-packages/wandb/sdk/lib/redirect.py", line 662, in _on_write
    cb(written_data)
  File "/home/vcivale/.local/lib/python3.10/site-packages/wandb/sdk/wandb_run.py", line 2379, in <lambda>
    lambda data: self._console_raw_callback("stdout", data),
  File "/home/vcivale/.local/lib/python3.10/site-packages/wandb/sdk/wandb_run.py", line 398, in wrapper
    return func(self, *args, **kwargs)
  File "/home/vcivale/.local/lib/python3.10/site-packages/wandb/sdk/wandb_run.py", line 456, in wrapper_fn
    return func(self, *args, **kwargs)
  File "/home/vcivale/.local/lib/python3.10/site-packages/wandb/sdk/wandb_run.py", line 1566, in _console_raw_callback
    self._backend.interface.publish_output_raw(name, data)
  File "/home/vcivale/.local/lib/python3.10/site-packages/wandb/sdk/interface/interface.py", line 771, in publish_output_raw
    self._publish_output_raw(o)
  File "/home/vcivale/.local/lib/python3.10/site-packages/wandb/sdk/interface/interface_shared.py", line 38, in _publish_output_raw
    self._publish(rec)
  File "/home/vcivale/.local/lib/python3.10/site-packages/wandb/sdk/interface/interface_sock.py", line 39, in _publish
    self._sock_client.send_record_publish(record)
  File "/home/vcivale/.local/lib/python3.10/site-packages/wandb/sdk/lib/sock_client.py", line 170, in send_record_publish
    self.send_server_request(server_req)
  File "/home/vcivale/.local/lib/python3.10/site-packages/wandb/sdk/lib/sock_client.py", line 150, in send_server_request
    self._send_message(msg)
  File "/home/vcivale/.local/lib/python3.10/site-packages/wandb/sdk/lib/sock_client.py", line 147, in _send_message
    self._sendall_with_error_handle(header + data)
  File "/home/vcivale/.local/lib/python3.10/site-packages/wandb/sdk/lib/sock_client.py", line 126, in _sendall_with_error_handle
    sent = self._sock.send(data)
BrokenPipeError: [Errno 32] Broken pipe
2025-07-07 13:09:40,288 INFO    MainThread:956308 [wandb_init.py:_post_run_cell_hook():592] [no run ID] resuming backend
2025-07-07 13:09:40,289 ERROR   MainThread:956308 [redirect.py:_on_write():664] [all runs] error in stdout callback
Traceback (most recent call last):
  File "/home/vcivale/.local/lib/python3.10/site-packages/IPython/core/events.py", line 82, in trigger
    func(*args, **kwargs)
  File "/home/vcivale/.local/lib/python3.10/site-packages/wandb/sdk/wandb_init.py", line 593, in _post_run_cell_hook
    self.backend.interface.publish_resume()
  File "/home/vcivale/.local/lib/python3.10/site-packages/wandb/sdk/interface/interface.py", line 787, in publish_resume
    self._publish_resume(resume)
  File "/home/vcivale/.local/lib/python3.10/site-packages/wandb/sdk/interface/interface_shared.py", line 294, in _publish_resume
    self._publish(rec)
  File "/home/vcivale/.local/lib/python3.10/site-packages/wandb/sdk/interface/interface_sock.py", line 39, in _publish
    self._sock_client.send_record_publish(record)
  File "/home/vcivale/.local/lib/python3.10/site-packages/wandb/sdk/lib/sock_client.py", line 170, in send_record_publish
    self.send_server_request(server_req)
  File "/home/vcivale/.local/lib/python3.10/site-packages/wandb/sdk/lib/sock_client.py", line 150, in send_server_request
    self._send_message(msg)
  File "/home/vcivale/.local/lib/python3.10/site-packages/wandb/sdk/lib/sock_client.py", line 147, in _send_message
    self._sendall_with_error_handle(header + data)
  File "/home/vcivale/.local/lib/python3.10/site-packages/wandb/sdk/lib/sock_client.py", line 126, in _sendall_with_error_handle
    sent = self._sock.send(data)
BrokenPipeError: [Errno 32] Broken pipe

During handling of the above exception, another exception occurred:

Traceback (most recent call last):
  File "/home/vcivale/.local/lib/python3.10/site-packages/wandb/sdk/lib/redirect.py", line 662, in _on_write
    cb(written_data)
  File "/home/vcivale/.local/lib/python3.10/site-packages/wandb/sdk/wandb_run.py", line 2379, in <lambda>
    lambda data: self._console_raw_callback("stdout", data),
  File "/home/vcivale/.local/lib/python3.10/site-packages/wandb/sdk/wandb_run.py", line 398, in wrapper
    return func(self, *args, **kwargs)
  File "/home/vcivale/.local/lib/python3.10/site-packages/wandb/sdk/wandb_run.py", line 456, in wrapper_fn
    return func(self, *args, **kwargs)
  File "/home/vcivale/.local/lib/python3.10/site-packages/wandb/sdk/wandb_run.py", line 1566, in _console_raw_callback
    self._backend.interface.publish_output_raw(name, data)
  File "/home/vcivale/.local/lib/python3.10/site-packages/wandb/sdk/interface/interface.py", line 771, in publish_output_raw
    self._publish_output_raw(o)
  File "/home/vcivale/.local/lib/python3.10/site-packages/wandb/sdk/interface/interface_shared.py", line 38, in _publish_output_raw
    self._publish(rec)
  File "/home/vcivale/.local/lib/python3.10/site-packages/wandb/sdk/interface/interface_sock.py", line 39, in _publish
    self._sock_client.send_record_publish(record)
  File "/home/vcivale/.local/lib/python3.10/site-packages/wandb/sdk/lib/sock_client.py", line 170, in send_record_publish
    self.send_server_request(server_req)
  File "/home/vcivale/.local/lib/python3.10/site-packages/wandb/sdk/lib/sock_client.py", line 150, in send_server_request
    self._send_message(msg)
  File "/home/vcivale/.local/lib/python3.10/site-packages/wandb/sdk/lib/sock_client.py", line 147, in _send_message
    self._sendall_with_error_handle(header + data)
  File "/home/vcivale/.local/lib/python3.10/site-packages/wandb/sdk/lib/sock_client.py", line 126, in _sendall_with_error_handle
    sent = self._sock.send(data)
BrokenPipeError: [Errno 32] Broken pipe
2025-07-07 13:09:40,290 ERROR   MainThread:956308 [redirect.py:_on_write():664] [all runs] error in stdout callback
Traceback (most recent call last):
  File "/home/vcivale/.local/lib/python3.10/site-packages/IPython/core/events.py", line 82, in trigger
    func(*args, **kwargs)
  File "/home/vcivale/.local/lib/python3.10/site-packages/wandb/sdk/wandb_init.py", line 593, in _post_run_cell_hook
    self.backend.interface.publish_resume()
  File "/home/vcivale/.local/lib/python3.10/site-packages/wandb/sdk/interface/interface.py", line 787, in publish_resume
    self._publish_resume(resume)
  File "/home/vcivale/.local/lib/python3.10/site-packages/wandb/sdk/interface/interface_shared.py", line 294, in _publish_resume
    self._publish(rec)
  File "/home/vcivale/.local/lib/python3.10/site-packages/wandb/sdk/interface/interface_sock.py", line 39, in _publish
    self._sock_client.send_record_publish(record)
  File "/home/vcivale/.local/lib/python3.10/site-packages/wandb/sdk/lib/sock_client.py", line 170, in send_record_publish
    self.send_server_request(server_req)
  File "/home/vcivale/.local/lib/python3.10/site-packages/wandb/sdk/lib/sock_client.py", line 150, in send_server_request
    self._send_message(msg)
  File "/home/vcivale/.local/lib/python3.10/site-packages/wandb/sdk/lib/sock_client.py", line 147, in _send_message
    self._sendall_with_error_handle(header + data)
  File "/home/vcivale/.local/lib/python3.10/site-packages/wandb/sdk/lib/sock_client.py", line 126, in _sendall_with_error_handle
    sent = self._sock.send(data)
BrokenPipeError: [Errno 32] Broken pipe

During handling of the above exception, another exception occurred:

Traceback (most recent call last):
  File "/home/vcivale/.local/lib/python3.10/site-packages/wandb/sdk/lib/redirect.py", line 662, in _on_write
    cb(written_data)
  File "/home/vcivale/.local/lib/python3.10/site-packages/wandb/sdk/wandb_run.py", line 2379, in <lambda>
    lambda data: self._console_raw_callback("stdout", data),
  File "/home/vcivale/.local/lib/python3.10/site-packages/wandb/sdk/wandb_run.py", line 398, in wrapper
    return func(self, *args, **kwargs)
  File "/home/vcivale/.local/lib/python3.10/site-packages/wandb/sdk/wandb_run.py", line 456, in wrapper_fn
    return func(self, *args, **kwargs)
  File "/home/vcivale/.local/lib/python3.10/site-packages/wandb/sdk/wandb_run.py", line 1566, in _console_raw_callback
    self._backend.interface.publish_output_raw(name, data)
  File "/home/vcivale/.local/lib/python3.10/site-packages/wandb/sdk/interface/interface.py", line 771, in publish_output_raw
    self._publish_output_raw(o)
  File "/home/vcivale/.local/lib/python3.10/site-packages/wandb/sdk/interface/interface_shared.py", line 38, in _publish_output_raw
    self._publish(rec)
  File "/home/vcivale/.local/lib/python3.10/site-packages/wandb/sdk/interface/interface_sock.py", line 39, in _publish
    self._sock_client.send_record_publish(record)
  File "/home/vcivale/.local/lib/python3.10/site-packages/wandb/sdk/lib/sock_client.py", line 170, in send_record_publish
    self.send_server_request(server_req)
  File "/home/vcivale/.local/lib/python3.10/site-packages/wandb/sdk/lib/sock_client.py", line 150, in send_server_request
    self._send_message(msg)
  File "/home/vcivale/.local/lib/python3.10/site-packages/wandb/sdk/lib/sock_client.py", line 147, in _send_message
    self._sendall_with_error_handle(header + data)
  File "/home/vcivale/.local/lib/python3.10/site-packages/wandb/sdk/lib/sock_client.py", line 126, in _sendall_with_error_handle
    sent = self._sock.send(data)
BrokenPipeError: [Errno 32] Broken pipe
2025-07-07 13:09:40,386 INFO    MainThread:956308 [jupyter.py:save_ipynb():404] [no run ID] not saving jupyter notebook
2025-07-07 13:09:40,386 INFO    MainThread:956308 [wandb_init.py:_pre_run_cell_hook():581] [no run ID] pausing backend
2025-07-07 13:09:40,387 ERROR   MainThread:956308 [redirect.py:_on_write():664] [all runs] error in stdout callback
Traceback (most recent call last):
  File "/home/vcivale/.local/lib/python3.10/site-packages/IPython/core/events.py", line 82, in trigger
    func(*args, **kwargs)
  File "/home/vcivale/.local/lib/python3.10/site-packages/wandb/sdk/wandb_init.py", line 582, in _pre_run_cell_hook
    self.backend.interface.publish_pause()
  File "/home/vcivale/.local/lib/python3.10/site-packages/wandb/sdk/interface/interface.py", line 779, in publish_pause
    self._publish_pause(pause)
  File "/home/vcivale/.local/lib/python3.10/site-packages/wandb/sdk/interface/interface_shared.py", line 290, in _publish_pause
    self._publish(rec)
  File "/home/vcivale/.local/lib/python3.10/site-packages/wandb/sdk/interface/interface_sock.py", line 39, in _publish
    self._sock_client.send_record_publish(record)
  File "/home/vcivale/.local/lib/python3.10/site-packages/wandb/sdk/lib/sock_client.py", line 170, in send_record_publish
    self.send_server_request(server_req)
  File "/home/vcivale/.local/lib/python3.10/site-packages/wandb/sdk/lib/sock_client.py", line 150, in send_server_request
    self._send_message(msg)
  File "/home/vcivale/.local/lib/python3.10/site-packages/wandb/sdk/lib/sock_client.py", line 147, in _send_message
    self._sendall_with_error_handle(header + data)
  File "/home/vcivale/.local/lib/python3.10/site-packages/wandb/sdk/lib/sock_client.py", line 126, in _sendall_with_error_handle
    sent = self._sock.send(data)
BrokenPipeError: [Errno 32] Broken pipe

During handling of the above exception, another exception occurred:

Traceback (most recent call last):
  File "/home/vcivale/.local/lib/python3.10/site-packages/wandb/sdk/lib/redirect.py", line 662, in _on_write
    cb(written_data)
  File "/home/vcivale/.local/lib/python3.10/site-packages/wandb/sdk/wandb_run.py", line 2379, in <lambda>
    lambda data: self._console_raw_callback("stdout", data),
  File "/home/vcivale/.local/lib/python3.10/site-packages/wandb/sdk/wandb_run.py", line 398, in wrapper
    return func(self, *args, **kwargs)
  File "/home/vcivale/.local/lib/python3.10/site-packages/wandb/sdk/wandb_run.py", line 456, in wrapper_fn
    return func(self, *args, **kwargs)
  File "/home/vcivale/.local/lib/python3.10/site-packages/wandb/sdk/wandb_run.py", line 1566, in _console_raw_callback
    self._backend.interface.publish_output_raw(name, data)
  File "/home/vcivale/.local/lib/python3.10/site-packages/wandb/sdk/interface/interface.py", line 771, in publish_output_raw
    self._publish_output_raw(o)
  File "/home/vcivale/.local/lib/python3.10/site-packages/wandb/sdk/interface/interface_shared.py", line 38, in _publish_output_raw
    self._publish(rec)
  File "/home/vcivale/.local/lib/python3.10/site-packages/wandb/sdk/interface/interface_sock.py", line 39, in _publish
    self._sock_client.send_record_publish(record)
  File "/home/vcivale/.local/lib/python3.10/site-packages/wandb/sdk/lib/sock_client.py", line 170, in send_record_publish
    self.send_server_request(server_req)
  File "/home/vcivale/.local/lib/python3.10/site-packages/wandb/sdk/lib/sock_client.py", line 150, in send_server_request
    self._send_message(msg)
  File "/home/vcivale/.local/lib/python3.10/site-packages/wandb/sdk/lib/sock_client.py", line 147, in _send_message
    self._sendall_with_error_handle(header + data)
  File "/home/vcivale/.local/lib/python3.10/site-packages/wandb/sdk/lib/sock_client.py", line 126, in _sendall_with_error_handle
    sent = self._sock.send(data)
BrokenPipeError: [Errno 32] Broken pipe
2025-07-07 13:09:40,388 ERROR   MainThread:956308 [redirect.py:_on_write():664] [all runs] error in stdout callback
Traceback (most recent call last):
  File "/home/vcivale/.local/lib/python3.10/site-packages/IPython/core/events.py", line 82, in trigger
    func(*args, **kwargs)
  File "/home/vcivale/.local/lib/python3.10/site-packages/wandb/sdk/wandb_init.py", line 582, in _pre_run_cell_hook
    self.backend.interface.publish_pause()
  File "/home/vcivale/.local/lib/python3.10/site-packages/wandb/sdk/interface/interface.py", line 779, in publish_pause
    self._publish_pause(pause)
  File "/home/vcivale/.local/lib/python3.10/site-packages/wandb/sdk/interface/interface_shared.py", line 290, in _publish_pause
    self._publish(rec)
  File "/home/vcivale/.local/lib/python3.10/site-packages/wandb/sdk/interface/interface_sock.py", line 39, in _publish
    self._sock_client.send_record_publish(record)
  File "/home/vcivale/.local/lib/python3.10/site-packages/wandb/sdk/lib/sock_client.py", line 170, in send_record_publish
    self.send_server_request(server_req)
  File "/home/vcivale/.local/lib/python3.10/site-packages/wandb/sdk/lib/sock_client.py", line 150, in send_server_request
    self._send_message(msg)
  File "/home/vcivale/.local/lib/python3.10/site-packages/wandb/sdk/lib/sock_client.py", line 147, in _send_message
    self._sendall_with_error_handle(header + data)
  File "/home/vcivale/.local/lib/python3.10/site-packages/wandb/sdk/lib/sock_client.py", line 126, in _sendall_with_error_handle
    sent = self._sock.send(data)
BrokenPipeError: [Errno 32] Broken pipe

During handling of the above exception, another exception occurred:

Traceback (most recent call last):
  File "/home/vcivale/.local/lib/python3.10/site-packages/wandb/sdk/lib/redirect.py", line 662, in _on_write
    cb(written_data)
  File "/home/vcivale/.local/lib/python3.10/site-packages/wandb/sdk/wandb_run.py", line 2379, in <lambda>
    lambda data: self._console_raw_callback("stdout", data),
  File "/home/vcivale/.local/lib/python3.10/site-packages/wandb/sdk/wandb_run.py", line 398, in wrapper
    return func(self, *args, **kwargs)
  File "/home/vcivale/.local/lib/python3.10/site-packages/wandb/sdk/wandb_run.py", line 456, in wrapper_fn
    return func(self, *args, **kwargs)
  File "/home/vcivale/.local/lib/python3.10/site-packages/wandb/sdk/wandb_run.py", line 1566, in _console_raw_callback
    self._backend.interface.publish_output_raw(name, data)
  File "/home/vcivale/.local/lib/python3.10/site-packages/wandb/sdk/interface/interface.py", line 771, in publish_output_raw
    self._publish_output_raw(o)
  File "/home/vcivale/.local/lib/python3.10/site-packages/wandb/sdk/interface/interface_shared.py", line 38, in _publish_output_raw
    self._publish(rec)
  File "/home/vcivale/.local/lib/python3.10/site-packages/wandb/sdk/interface/interface_sock.py", line 39, in _publish
    self._sock_client.send_record_publish(record)
  File "/home/vcivale/.local/lib/python3.10/site-packages/wandb/sdk/lib/sock_client.py", line 170, in send_record_publish
    self.send_server_request(server_req)
  File "/home/vcivale/.local/lib/python3.10/site-packages/wandb/sdk/lib/sock_client.py", line 150, in send_server_request
    self._send_message(msg)
  File "/home/vcivale/.local/lib/python3.10/site-packages/wandb/sdk/lib/sock_client.py", line 147, in _send_message
    self._sendall_with_error_handle(header + data)
  File "/home/vcivale/.local/lib/python3.10/site-packages/wandb/sdk/lib/sock_client.py", line 126, in _sendall_with_error_handle
    sent = self._sock.send(data)
BrokenPipeError: [Errno 32] Broken pipe
2025-07-07 13:09:40,447 ERROR   MainThread:956308 [redirect.py:_on_write():664] [all runs] error in stdout callback
Traceback (most recent call last):
  File "/home/vcivale/.local/lib/python3.10/site-packages/wandb/sdk/lib/redirect.py", line 662, in _on_write
    cb(written_data)
  File "/home/vcivale/.local/lib/python3.10/site-packages/wandb/sdk/wandb_run.py", line 2379, in <lambda>
    lambda data: self._console_raw_callback("stdout", data),
  File "/home/vcivale/.local/lib/python3.10/site-packages/wandb/sdk/wandb_run.py", line 398, in wrapper
    return func(self, *args, **kwargs)
  File "/home/vcivale/.local/lib/python3.10/site-packages/wandb/sdk/wandb_run.py", line 456, in wrapper_fn
    return func(self, *args, **kwargs)
  File "/home/vcivale/.local/lib/python3.10/site-packages/wandb/sdk/wandb_run.py", line 1566, in _console_raw_callback
    self._backend.interface.publish_output_raw(name, data)
  File "/home/vcivale/.local/lib/python3.10/site-packages/wandb/sdk/interface/interface.py", line 771, in publish_output_raw
    self._publish_output_raw(o)
  File "/home/vcivale/.local/lib/python3.10/site-packages/wandb/sdk/interface/interface_shared.py", line 38, in _publish_output_raw
    self._publish(rec)
  File "/home/vcivale/.local/lib/python3.10/site-packages/wandb/sdk/interface/interface_sock.py", line 39, in _publish
    self._sock_client.send_record_publish(record)
  File "/home/vcivale/.local/lib/python3.10/site-packages/wandb/sdk/lib/sock_client.py", line 170, in send_record_publish
    self.send_server_request(server_req)
  File "/home/vcivale/.local/lib/python3.10/site-packages/wandb/sdk/lib/sock_client.py", line 150, in send_server_request
    self._send_message(msg)
  File "/home/vcivale/.local/lib/python3.10/site-packages/wandb/sdk/lib/sock_client.py", line 147, in _send_message
    self._sendall_with_error_handle(header + data)
  File "/home/vcivale/.local/lib/python3.10/site-packages/wandb/sdk/lib/sock_client.py", line 126, in _sendall_with_error_handle
    sent = self._sock.send(data)
BrokenPipeError: [Errno 32] Broken pipe
2025-07-07 13:09:40,448 ERROR   MainThread:956308 [redirect.py:_on_write():664] [all runs] error in stdout callback
Traceback (most recent call last):
  File "/home/vcivale/.local/lib/python3.10/site-packages/wandb/sdk/lib/redirect.py", line 662, in _on_write
    cb(written_data)
  File "/home/vcivale/.local/lib/python3.10/site-packages/wandb/sdk/wandb_run.py", line 2379, in <lambda>
    lambda data: self._console_raw_callback("stdout", data),
  File "/home/vcivale/.local/lib/python3.10/site-packages/wandb/sdk/wandb_run.py", line 398, in wrapper
    return func(self, *args, **kwargs)
  File "/home/vcivale/.local/lib/python3.10/site-packages/wandb/sdk/wandb_run.py", line 456, in wrapper_fn
    return func(self, *args, **kwargs)
  File "/home/vcivale/.local/lib/python3.10/site-packages/wandb/sdk/wandb_run.py", line 1566, in _console_raw_callback
    self._backend.interface.publish_output_raw(name, data)
  File "/home/vcivale/.local/lib/python3.10/site-packages/wandb/sdk/interface/interface.py", line 771, in publish_output_raw
    self._publish_output_raw(o)
  File "/home/vcivale/.local/lib/python3.10/site-packages/wandb/sdk/interface/interface_shared.py", line 38, in _publish_output_raw
    self._publish(rec)
  File "/home/vcivale/.local/lib/python3.10/site-packages/wandb/sdk/interface/interface_sock.py", line 39, in _publish
    self._sock_client.send_record_publish(record)
  File "/home/vcivale/.local/lib/python3.10/site-packages/wandb/sdk/lib/sock_client.py", line 170, in send_record_publish
    self.send_server_request(server_req)
  File "/home/vcivale/.local/lib/python3.10/site-packages/wandb/sdk/lib/sock_client.py", line 150, in send_server_request
    self._send_message(msg)
  File "/home/vcivale/.local/lib/python3.10/site-packages/wandb/sdk/lib/sock_client.py", line 147, in _send_message
    self._sendall_with_error_handle(header + data)
  File "/home/vcivale/.local/lib/python3.10/site-packages/wandb/sdk/lib/sock_client.py", line 126, in _sendall_with_error_handle
    sent = self._sock.send(data)
BrokenPipeError: [Errno 32] Broken pipe
2025-07-07 13:09:43,756 ERROR   MainThread:956308 [redirect.py:_on_write():664] [all runs] error in stdout callback
Traceback (most recent call last):
  File "/home/vcivale/.local/lib/python3.10/site-packages/wandb/sdk/lib/redirect.py", line 662, in _on_write
    cb(written_data)
  File "/home/vcivale/.local/lib/python3.10/site-packages/wandb/sdk/wandb_run.py", line 2379, in <lambda>
    lambda data: self._console_raw_callback("stdout", data),
  File "/home/vcivale/.local/lib/python3.10/site-packages/wandb/sdk/wandb_run.py", line 398, in wrapper
    return func(self, *args, **kwargs)
  File "/home/vcivale/.local/lib/python3.10/site-packages/wandb/sdk/wandb_run.py", line 456, in wrapper_fn
    return func(self, *args, **kwargs)
  File "/home/vcivale/.local/lib/python3.10/site-packages/wandb/sdk/wandb_run.py", line 1566, in _console_raw_callback
    self._backend.interface.publish_output_raw(name, data)
  File "/home/vcivale/.local/lib/python3.10/site-packages/wandb/sdk/interface/interface.py", line 771, in publish_output_raw
    self._publish_output_raw(o)
  File "/home/vcivale/.local/lib/python3.10/site-packages/wandb/sdk/interface/interface_shared.py", line 38, in _publish_output_raw
    self._publish(rec)
  File "/home/vcivale/.local/lib/python3.10/site-packages/wandb/sdk/interface/interface_sock.py", line 39, in _publish
    self._sock_client.send_record_publish(record)
  File "/home/vcivale/.local/lib/python3.10/site-packages/wandb/sdk/lib/sock_client.py", line 170, in send_record_publish
    self.send_server_request(server_req)
  File "/home/vcivale/.local/lib/python3.10/site-packages/wandb/sdk/lib/sock_client.py", line 150, in send_server_request
    self._send_message(msg)
  File "/home/vcivale/.local/lib/python3.10/site-packages/wandb/sdk/lib/sock_client.py", line 147, in _send_message
    self._sendall_with_error_handle(header + data)
  File "/home/vcivale/.local/lib/python3.10/site-packages/wandb/sdk/lib/sock_client.py", line 126, in _sendall_with_error_handle
    sent = self._sock.send(data)
BrokenPipeError: [Errno 32] Broken pipe
2025-07-07 13:09:43,757 ERROR   MainThread:956308 [redirect.py:_on_write():664] [all runs] error in stdout callback
Traceback (most recent call last):
  File "/home/vcivale/.local/lib/python3.10/site-packages/wandb/sdk/lib/redirect.py", line 662, in _on_write
    cb(written_data)
  File "/home/vcivale/.local/lib/python3.10/site-packages/wandb/sdk/wandb_run.py", line 2379, in <lambda>
    lambda data: self._console_raw_callback("stdout", data),
  File "/home/vcivale/.local/lib/python3.10/site-packages/wandb/sdk/wandb_run.py", line 398, in wrapper
    return func(self, *args, **kwargs)
  File "/home/vcivale/.local/lib/python3.10/site-packages/wandb/sdk/wandb_run.py", line 456, in wrapper_fn
    return func(self, *args, **kwargs)
  File "/home/vcivale/.local/lib/python3.10/site-packages/wandb/sdk/wandb_run.py", line 1566, in _console_raw_callback
    self._backend.interface.publish_output_raw(name, data)
  File "/home/vcivale/.local/lib/python3.10/site-packages/wandb/sdk/interface/interface.py", line 771, in publish_output_raw
    self._publish_output_raw(o)
  File "/home/vcivale/.local/lib/python3.10/site-packages/wandb/sdk/interface/interface_shared.py", line 38, in _publish_output_raw
    self._publish(rec)
  File "/home/vcivale/.local/lib/python3.10/site-packages/wandb/sdk/interface/interface_sock.py", line 39, in _publish
    self._sock_client.send_record_publish(record)
  File "/home/vcivale/.local/lib/python3.10/site-packages/wandb/sdk/lib/sock_client.py", line 170, in send_record_publish
    self.send_server_request(server_req)
  File "/home/vcivale/.local/lib/python3.10/site-packages/wandb/sdk/lib/sock_client.py", line 150, in send_server_request
    self._send_message(msg)
  File "/home/vcivale/.local/lib/python3.10/site-packages/wandb/sdk/lib/sock_client.py", line 147, in _send_message
    self._sendall_with_error_handle(header + data)
  File "/home/vcivale/.local/lib/python3.10/site-packages/wandb/sdk/lib/sock_client.py", line 126, in _sendall_with_error_handle
    sent = self._sock.send(data)
BrokenPipeError: [Errno 32] Broken pipe
2025-07-07 13:09:44,961 ERROR   MainThread:956308 [redirect.py:_on_write():664] [all runs] error in stdout callback
Traceback (most recent call last):
  File "/home/vcivale/.local/lib/python3.10/site-packages/wandb/sdk/lib/redirect.py", line 662, in _on_write
    cb(written_data)
  File "/home/vcivale/.local/lib/python3.10/site-packages/wandb/sdk/wandb_run.py", line 2379, in <lambda>
    lambda data: self._console_raw_callback("stdout", data),
  File "/home/vcivale/.local/lib/python3.10/site-packages/wandb/sdk/wandb_run.py", line 398, in wrapper
    return func(self, *args, **kwargs)
  File "/home/vcivale/.local/lib/python3.10/site-packages/wandb/sdk/wandb_run.py", line 456, in wrapper_fn
    return func(self, *args, **kwargs)
  File "/home/vcivale/.local/lib/python3.10/site-packages/wandb/sdk/wandb_run.py", line 1566, in _console_raw_callback
    self._backend.interface.publish_output_raw(name, data)
  File "/home/vcivale/.local/lib/python3.10/site-packages/wandb/sdk/interface/interface.py", line 771, in publish_output_raw
    self._publish_output_raw(o)
  File "/home/vcivale/.local/lib/python3.10/site-packages/wandb/sdk/interface/interface_shared.py", line 38, in _publish_output_raw
    self._publish(rec)
  File "/home/vcivale/.local/lib/python3.10/site-packages/wandb/sdk/interface/interface_sock.py", line 39, in _publish
    self._sock_client.send_record_publish(record)
  File "/home/vcivale/.local/lib/python3.10/site-packages/wandb/sdk/lib/sock_client.py", line 170, in send_record_publish
    self.send_server_request(server_req)
  File "/home/vcivale/.local/lib/python3.10/site-packages/wandb/sdk/lib/sock_client.py", line 150, in send_server_request
    self._send_message(msg)
  File "/home/vcivale/.local/lib/python3.10/site-packages/wandb/sdk/lib/sock_client.py", line 147, in _send_message
    self._sendall_with_error_handle(header + data)
  File "/home/vcivale/.local/lib/python3.10/site-packages/wandb/sdk/lib/sock_client.py", line 126, in _sendall_with_error_handle
    sent = self._sock.send(data)
BrokenPipeError: [Errno 32] Broken pipe
2025-07-07 13:09:44,962 ERROR   MainThread:956308 [redirect.py:_on_write():664] [all runs] error in stdout callback
Traceback (most recent call last):
  File "/home/vcivale/.local/lib/python3.10/site-packages/wandb/sdk/lib/redirect.py", line 662, in _on_write
    cb(written_data)
  File "/home/vcivale/.local/lib/python3.10/site-packages/wandb/sdk/wandb_run.py", line 2379, in <lambda>
    lambda data: self._console_raw_callback("stdout", data),
  File "/home/vcivale/.local/lib/python3.10/site-packages/wandb/sdk/wandb_run.py", line 398, in wrapper
    return func(self, *args, **kwargs)
  File "/home/vcivale/.local/lib/python3.10/site-packages/wandb/sdk/wandb_run.py", line 456, in wrapper_fn
    return func(self, *args, **kwargs)
  File "/home/vcivale/.local/lib/python3.10/site-packages/wandb/sdk/wandb_run.py", line 1566, in _console_raw_callback
    self._backend.interface.publish_output_raw(name, data)
  File "/home/vcivale/.local/lib/python3.10/site-packages/wandb/sdk/interface/interface.py", line 771, in publish_output_raw
    self._publish_output_raw(o)
  File "/home/vcivale/.local/lib/python3.10/site-packages/wandb/sdk/interface/interface_shared.py", line 38, in _publish_output_raw
    self._publish(rec)
  File "/home/vcivale/.local/lib/python3.10/site-packages/wandb/sdk/interface/interface_sock.py", line 39, in _publish
    self._sock_client.send_record_publish(record)
  File "/home/vcivale/.local/lib/python3.10/site-packages/wandb/sdk/lib/sock_client.py", line 170, in send_record_publish
    self.send_server_request(server_req)
  File "/home/vcivale/.local/lib/python3.10/site-packages/wandb/sdk/lib/sock_client.py", line 150, in send_server_request
    self._send_message(msg)
  File "/home/vcivale/.local/lib/python3.10/site-packages/wandb/sdk/lib/sock_client.py", line 147, in _send_message
    self._sendall_with_error_handle(header + data)
  File "/home/vcivale/.local/lib/python3.10/site-packages/wandb/sdk/lib/sock_client.py", line 126, in _sendall_with_error_handle
    sent = self._sock.send(data)
BrokenPipeError: [Errno 32] Broken pipe
2025-07-07 13:09:46,792 INFO    MainThread:956308 [wandb_init.py:_post_run_cell_hook():592] [no run ID] resuming backend
2025-07-07 13:09:46,793 ERROR   MainThread:956308 [redirect.py:_on_write():664] [all runs] error in stdout callback
Traceback (most recent call last):
  File "/home/vcivale/.local/lib/python3.10/site-packages/IPython/core/events.py", line 82, in trigger
    func(*args, **kwargs)
  File "/home/vcivale/.local/lib/python3.10/site-packages/wandb/sdk/wandb_init.py", line 593, in _post_run_cell_hook
    self.backend.interface.publish_resume()
  File "/home/vcivale/.local/lib/python3.10/site-packages/wandb/sdk/interface/interface.py", line 787, in publish_resume
    self._publish_resume(resume)
  File "/home/vcivale/.local/lib/python3.10/site-packages/wandb/sdk/interface/interface_shared.py", line 294, in _publish_resume
    self._publish(rec)
  File "/home/vcivale/.local/lib/python3.10/site-packages/wandb/sdk/interface/interface_sock.py", line 39, in _publish
    self._sock_client.send_record_publish(record)
  File "/home/vcivale/.local/lib/python3.10/site-packages/wandb/sdk/lib/sock_client.py", line 170, in send_record_publish
    self.send_server_request(server_req)
  File "/home/vcivale/.local/lib/python3.10/site-packages/wandb/sdk/lib/sock_client.py", line 150, in send_server_request
    self._send_message(msg)
  File "/home/vcivale/.local/lib/python3.10/site-packages/wandb/sdk/lib/sock_client.py", line 147, in _send_message
    self._sendall_with_error_handle(header + data)
  File "/home/vcivale/.local/lib/python3.10/site-packages/wandb/sdk/lib/sock_client.py", line 126, in _sendall_with_error_handle
    sent = self._sock.send(data)
BrokenPipeError: [Errno 32] Broken pipe

During handling of the above exception, another exception occurred:

Traceback (most recent call last):
  File "/home/vcivale/.local/lib/python3.10/site-packages/wandb/sdk/lib/redirect.py", line 662, in _on_write
    cb(written_data)
  File "/home/vcivale/.local/lib/python3.10/site-packages/wandb/sdk/wandb_run.py", line 2379, in <lambda>
    lambda data: self._console_raw_callback("stdout", data),
  File "/home/vcivale/.local/lib/python3.10/site-packages/wandb/sdk/wandb_run.py", line 398, in wrapper
    return func(self, *args, **kwargs)
  File "/home/vcivale/.local/lib/python3.10/site-packages/wandb/sdk/wandb_run.py", line 456, in wrapper_fn
    return func(self, *args, **kwargs)
  File "/home/vcivale/.local/lib/python3.10/site-packages/wandb/sdk/wandb_run.py", line 1566, in _console_raw_callback
    self._backend.interface.publish_output_raw(name, data)
  File "/home/vcivale/.local/lib/python3.10/site-packages/wandb/sdk/interface/interface.py", line 771, in publish_output_raw
    self._publish_output_raw(o)
  File "/home/vcivale/.local/lib/python3.10/site-packages/wandb/sdk/interface/interface_shared.py", line 38, in _publish_output_raw
    self._publish(rec)
  File "/home/vcivale/.local/lib/python3.10/site-packages/wandb/sdk/interface/interface_sock.py", line 39, in _publish
    self._sock_client.send_record_publish(record)
  File "/home/vcivale/.local/lib/python3.10/site-packages/wandb/sdk/lib/sock_client.py", line 170, in send_record_publish
    self.send_server_request(server_req)
  File "/home/vcivale/.local/lib/python3.10/site-packages/wandb/sdk/lib/sock_client.py", line 150, in send_server_request
    self._send_message(msg)
  File "/home/vcivale/.local/lib/python3.10/site-packages/wandb/sdk/lib/sock_client.py", line 147, in _send_message
    self._sendall_with_error_handle(header + data)
  File "/home/vcivale/.local/lib/python3.10/site-packages/wandb/sdk/lib/sock_client.py", line 126, in _sendall_with_error_handle
    sent = self._sock.send(data)
BrokenPipeError: [Errno 32] Broken pipe
2025-07-07 13:09:46,794 ERROR   MainThread:956308 [redirect.py:_on_write():664] [all runs] error in stdout callback
Traceback (most recent call last):
  File "/home/vcivale/.local/lib/python3.10/site-packages/IPython/core/events.py", line 82, in trigger
    func(*args, **kwargs)
  File "/home/vcivale/.local/lib/python3.10/site-packages/wandb/sdk/wandb_init.py", line 593, in _post_run_cell_hook
    self.backend.interface.publish_resume()
  File "/home/vcivale/.local/lib/python3.10/site-packages/wandb/sdk/interface/interface.py", line 787, in publish_resume
    self._publish_resume(resume)
  File "/home/vcivale/.local/lib/python3.10/site-packages/wandb/sdk/interface/interface_shared.py", line 294, in _publish_resume
    self._publish(rec)
  File "/home/vcivale/.local/lib/python3.10/site-packages/wandb/sdk/interface/interface_sock.py", line 39, in _publish
    self._sock_client.send_record_publish(record)
  File "/home/vcivale/.local/lib/python3.10/site-packages/wandb/sdk/lib/sock_client.py", line 170, in send_record_publish
    self.send_server_request(server_req)
  File "/home/vcivale/.local/lib/python3.10/site-packages/wandb/sdk/lib/sock_client.py", line 150, in send_server_request
    self._send_message(msg)
  File "/home/vcivale/.local/lib/python3.10/site-packages/wandb/sdk/lib/sock_client.py", line 147, in _send_message
    self._sendall_with_error_handle(header + data)
  File "/home/vcivale/.local/lib/python3.10/site-packages/wandb/sdk/lib/sock_client.py", line 126, in _sendall_with_error_handle
    sent = self._sock.send(data)
BrokenPipeError: [Errno 32] Broken pipe

During handling of the above exception, another exception occurred:

Traceback (most recent call last):
  File "/home/vcivale/.local/lib/python3.10/site-packages/wandb/sdk/lib/redirect.py", line 662, in _on_write
    cb(written_data)
  File "/home/vcivale/.local/lib/python3.10/site-packages/wandb/sdk/wandb_run.py", line 2379, in <lambda>
    lambda data: self._console_raw_callback("stdout", data),
  File "/home/vcivale/.local/lib/python3.10/site-packages/wandb/sdk/wandb_run.py", line 398, in wrapper
    return func(self, *args, **kwargs)
  File "/home/vcivale/.local/lib/python3.10/site-packages/wandb/sdk/wandb_run.py", line 456, in wrapper_fn
    return func(self, *args, **kwargs)
  File "/home/vcivale/.local/lib/python3.10/site-packages/wandb/sdk/wandb_run.py", line 1566, in _console_raw_callback
    self._backend.interface.publish_output_raw(name, data)
  File "/home/vcivale/.local/lib/python3.10/site-packages/wandb/sdk/interface/interface.py", line 771, in publish_output_raw
    self._publish_output_raw(o)
  File "/home/vcivale/.local/lib/python3.10/site-packages/wandb/sdk/interface/interface_shared.py", line 38, in _publish_output_raw
    self._publish(rec)
  File "/home/vcivale/.local/lib/python3.10/site-packages/wandb/sdk/interface/interface_sock.py", line 39, in _publish
    self._sock_client.send_record_publish(record)
  File "/home/vcivale/.local/lib/python3.10/site-packages/wandb/sdk/lib/sock_client.py", line 170, in send_record_publish
    self.send_server_request(server_req)
  File "/home/vcivale/.local/lib/python3.10/site-packages/wandb/sdk/lib/sock_client.py", line 150, in send_server_request
    self._send_message(msg)
  File "/home/vcivale/.local/lib/python3.10/site-packages/wandb/sdk/lib/sock_client.py", line 147, in _send_message
    self._sendall_with_error_handle(header + data)
  File "/home/vcivale/.local/lib/python3.10/site-packages/wandb/sdk/lib/sock_client.py", line 126, in _sendall_with_error_handle
    sent = self._sock.send(data)
BrokenPipeError: [Errno 32] Broken pipe
2025-07-07 13:09:46,902 INFO    MainThread:956308 [jupyter.py:save_ipynb():404] [no run ID] not saving jupyter notebook
2025-07-07 13:09:46,902 INFO    MainThread:956308 [wandb_init.py:_pre_run_cell_hook():581] [no run ID] pausing backend
2025-07-07 13:09:46,902 ERROR   MainThread:956308 [redirect.py:_on_write():664] [all runs] error in stdout callback
Traceback (most recent call last):
  File "/home/vcivale/.local/lib/python3.10/site-packages/IPython/core/events.py", line 82, in trigger
    func(*args, **kwargs)
  File "/home/vcivale/.local/lib/python3.10/site-packages/wandb/sdk/wandb_init.py", line 582, in _pre_run_cell_hook
    self.backend.interface.publish_pause()
  File "/home/vcivale/.local/lib/python3.10/site-packages/wandb/sdk/interface/interface.py", line 779, in publish_pause
    self._publish_pause(pause)
  File "/home/vcivale/.local/lib/python3.10/site-packages/wandb/sdk/interface/interface_shared.py", line 290, in _publish_pause
    self._publish(rec)
  File "/home/vcivale/.local/lib/python3.10/site-packages/wandb/sdk/interface/interface_sock.py", line 39, in _publish
    self._sock_client.send_record_publish(record)
  File "/home/vcivale/.local/lib/python3.10/site-packages/wandb/sdk/lib/sock_client.py", line 170, in send_record_publish
    self.send_server_request(server_req)
  File "/home/vcivale/.local/lib/python3.10/site-packages/wandb/sdk/lib/sock_client.py", line 150, in send_server_request
    self._send_message(msg)
  File "/home/vcivale/.local/lib/python3.10/site-packages/wandb/sdk/lib/sock_client.py", line 147, in _send_message
    self._sendall_with_error_handle(header + data)
  File "/home/vcivale/.local/lib/python3.10/site-packages/wandb/sdk/lib/sock_client.py", line 126, in _sendall_with_error_handle
    sent = self._sock.send(data)
BrokenPipeError: [Errno 32] Broken pipe

During handling of the above exception, another exception occurred:

Traceback (most recent call last):
  File "/home/vcivale/.local/lib/python3.10/site-packages/wandb/sdk/lib/redirect.py", line 662, in _on_write
    cb(written_data)
  File "/home/vcivale/.local/lib/python3.10/site-packages/wandb/sdk/wandb_run.py", line 2379, in <lambda>
    lambda data: self._console_raw_callback("stdout", data),
  File "/home/vcivale/.local/lib/python3.10/site-packages/wandb/sdk/wandb_run.py", line 398, in wrapper
    return func(self, *args, **kwargs)
  File "/home/vcivale/.local/lib/python3.10/site-packages/wandb/sdk/wandb_run.py", line 456, in wrapper_fn
    return func(self, *args, **kwargs)
  File "/home/vcivale/.local/lib/python3.10/site-packages/wandb/sdk/wandb_run.py", line 1566, in _console_raw_callback
    self._backend.interface.publish_output_raw(name, data)
  File "/home/vcivale/.local/lib/python3.10/site-packages/wandb/sdk/interface/interface.py", line 771, in publish_output_raw
    self._publish_output_raw(o)
  File "/home/vcivale/.local/lib/python3.10/site-packages/wandb/sdk/interface/interface_shared.py", line 38, in _publish_output_raw
    self._publish(rec)
  File "/home/vcivale/.local/lib/python3.10/site-packages/wandb/sdk/interface/interface_sock.py", line 39, in _publish
    self._sock_client.send_record_publish(record)
  File "/home/vcivale/.local/lib/python3.10/site-packages/wandb/sdk/lib/sock_client.py", line 170, in send_record_publish
    self.send_server_request(server_req)
  File "/home/vcivale/.local/lib/python3.10/site-packages/wandb/sdk/lib/sock_client.py", line 150, in send_server_request
    self._send_message(msg)
  File "/home/vcivale/.local/lib/python3.10/site-packages/wandb/sdk/lib/sock_client.py", line 147, in _send_message
    self._sendall_with_error_handle(header + data)
  File "/home/vcivale/.local/lib/python3.10/site-packages/wandb/sdk/lib/sock_client.py", line 126, in _sendall_with_error_handle
    sent = self._sock.send(data)
BrokenPipeError: [Errno 32] Broken pipe
2025-07-07 13:09:46,904 ERROR   MainThread:956308 [redirect.py:_on_write():664] [all runs] error in stdout callback
Traceback (most recent call last):
  File "/home/vcivale/.local/lib/python3.10/site-packages/IPython/core/events.py", line 82, in trigger
    func(*args, **kwargs)
  File "/home/vcivale/.local/lib/python3.10/site-packages/wandb/sdk/wandb_init.py", line 582, in _pre_run_cell_hook
    self.backend.interface.publish_pause()
  File "/home/vcivale/.local/lib/python3.10/site-packages/wandb/sdk/interface/interface.py", line 779, in publish_pause
    self._publish_pause(pause)
  File "/home/vcivale/.local/lib/python3.10/site-packages/wandb/sdk/interface/interface_shared.py", line 290, in _publish_pause
    self._publish(rec)
  File "/home/vcivale/.local/lib/python3.10/site-packages/wandb/sdk/interface/interface_sock.py", line 39, in _publish
    self._sock_client.send_record_publish(record)
  File "/home/vcivale/.local/lib/python3.10/site-packages/wandb/sdk/lib/sock_client.py", line 170, in send_record_publish
    self.send_server_request(server_req)
  File "/home/vcivale/.local/lib/python3.10/site-packages/wandb/sdk/lib/sock_client.py", line 150, in send_server_request
    self._send_message(msg)
  File "/home/vcivale/.local/lib/python3.10/site-packages/wandb/sdk/lib/sock_client.py", line 147, in _send_message
    self._sendall_with_error_handle(header + data)
  File "/home/vcivale/.local/lib/python3.10/site-packages/wandb/sdk/lib/sock_client.py", line 126, in _sendall_with_error_handle
    sent = self._sock.send(data)
BrokenPipeError: [Errno 32] Broken pipe

During handling of the above exception, another exception occurred:

Traceback (most recent call last):
  File "/home/vcivale/.local/lib/python3.10/site-packages/wandb/sdk/lib/redirect.py", line 662, in _on_write
    cb(written_data)
  File "/home/vcivale/.local/lib/python3.10/site-packages/wandb/sdk/wandb_run.py", line 2379, in <lambda>
    lambda data: self._console_raw_callback("stdout", data),
  File "/home/vcivale/.local/lib/python3.10/site-packages/wandb/sdk/wandb_run.py", line 398, in wrapper
    return func(self, *args, **kwargs)
  File "/home/vcivale/.local/lib/python3.10/site-packages/wandb/sdk/wandb_run.py", line 456, in wrapper_fn
    return func(self, *args, **kwargs)
  File "/home/vcivale/.local/lib/python3.10/site-packages/wandb/sdk/wandb_run.py", line 1566, in _console_raw_callback
    self._backend.interface.publish_output_raw(name, data)
  File "/home/vcivale/.local/lib/python3.10/site-packages/wandb/sdk/interface/interface.py", line 771, in publish_output_raw
    self._publish_output_raw(o)
  File "/home/vcivale/.local/lib/python3.10/site-packages/wandb/sdk/interface/interface_shared.py", line 38, in _publish_output_raw
    self._publish(rec)
  File "/home/vcivale/.local/lib/python3.10/site-packages/wandb/sdk/interface/interface_sock.py", line 39, in _publish
    self._sock_client.send_record_publish(record)
  File "/home/vcivale/.local/lib/python3.10/site-packages/wandb/sdk/lib/sock_client.py", line 170, in send_record_publish
    self.send_server_request(server_req)
  File "/home/vcivale/.local/lib/python3.10/site-packages/wandb/sdk/lib/sock_client.py", line 150, in send_server_request
    self._send_message(msg)
  File "/home/vcivale/.local/lib/python3.10/site-packages/wandb/sdk/lib/sock_client.py", line 147, in _send_message
    self._sendall_with_error_handle(header + data)
  File "/home/vcivale/.local/lib/python3.10/site-packages/wandb/sdk/lib/sock_client.py", line 126, in _sendall_with_error_handle
    sent = self._sock.send(data)
BrokenPipeError: [Errno 32] Broken pipe
